Workbook

Sheet 📊 Dashboard
J1: =MAX(SUMPRODUCT((Transactions!$A$2:$A$501<>"")*(MONTH(Transactions!$A$2:$A$501)=1)*(YEAR(Transactions!$A$2:$A$501)=YEAR(TODAY()))*(Transactions!$C$2:$C$501="Dépense")*Transactions!$D$2:$D$501),SUMPRODUCT((Transactions!$A$2:$A$501<>"")*(MONTH(Transactions!$A$2:$A$501)=2)*(YEAR(Transactions!$A$2:$A$501)=YEAR(TODAY()))*(Transactions!$C$2:$C$501="Dépense")*Transactions!$D$2:$D$501),SUMPRODUCT((Transactions!$A$2:$A$501<>"")*(MONTH(Transactions!$A$2:$A$501)=3)*(YEAR(Transactions!$A$2:$A$501)=YEAR(TODAY()))*(Transactions!$C$2:$C$501="Dépense")*Transactions!$D$2:$D$501),SUMPRODUCT((Transactions!$A$2:$A$501<>"")*(MONTH(Transactions!$A$2:$A$501)=4)*(YEAR(Transactions!$A$2:$A$501)=YEAR(TODAY()))*(Transactions!$C$2:$C$501="Dépense")*Transactions!$D$2:$D$501),SUMPRODUCT((Transactions!$A$2:$A$501<>"")*(MONTH(Transactions!$A$2:$A$501)=5)*(YEAR(Transactions!$A$2:$A$501)=YEAR(TODAY()))*(Transactions!$C$2:$C$501="Dépense")*Transactions!$D$2:$D$501),SUMPRODUCT((Transactions!$A$2:$A$501<>"")*(MONTH(Transactions!$A$2:$A$501)=6)*(YEAR(Transactions!$A$2:$A$501)=YEAR(TODAY()))*(Transactions!$C$2:$C$501="Dépense")*Transactions!$D$2:$D$501),SUMPRODUCT((Transactions!$A$2:$A$501<>"")*(MONTH(Transactions!$A$2:$A$501)=7)*(YEAR(Transactions!$A$2:$A$501)=YEAR(TODAY()))*(Transactions!$C$2:$C$501="Dépense")*Transactions!$D$2:$D$501),SUMPRODUCT((Transactions!$A$2:$A$501<>"")*(MONTH(Transactions!$A$2:$A$501)=8)*(YEAR(Transactions!$A$2:$A$501)=YEAR(TODAY()))*(Transactions!$C$2:$C$501="Dépense")*Transactions!$D$2:$D$501),SUMPRODUCT((Transactions!$A$2:$A$501<>"")*(MONTH(Transactions!$A$2:$A$501)=9)*(YEAR(Transactions!$A$2:$A$501)=YEAR(TODAY()))*(Transactions!$C$2:$C$501="Dépense")*Transactions!$D$2:$D$501),SUMPRODUCT((Transactions!$A$2:$A$501<>"")*(MONTH(Transactions!$A$2:$A$501)=10)*(YEAR(Transactions!$A$2:$A$501)=YEAR(TODAY()))*(Transactions!$C$2:$C$501="Dépense")*Transactions!$D$2:$D$501),SUMPRODUCT((Transactions!$A$2:$A$501<>"")*(MONTH(Transactions!$A$2:$A$501)=11)*(YEAR(Transactions!$A$2:$A$501)=YEAR(TODAY()))*(Transactions!$C$2:$C$501="Dépense")*Transactions!$D$2:$D$501),SUMPRODUCT((Transactions!$A$2:$A$501<>"")*(MONTH(Transactions!$A$2:$A$501)=12)*(YEAR(Transactions!$A$2:$A$501)=YEAR(TODAY()))*(Transactions!$C$2:$C$501="Dépense")*Transactions!$D$2:$D$501))
B2: FINANCES 360° tableau de bord personnel
B5: =UPPER(TEXT(TODAY(),"mmmm yyyy")) | F5: ="Jour "&DAY(TODAY())&" / "&DAY(EOMONTH(TODAY(),0)) | H5: → Saisir
B7: ◆ INDICATEURS DU MOIS EN COURS
B8: 💼 REVENUS | E8: 💸 DÉPENSES | G8: 💚 ÉPARGNE | I8: %
B9: =SUMPRODUCT((Transactions!$A$2:$A$501<>"")*(MONTH(Transactions!$A$2:$A$501)=MONTH(TODAY()))*(YEAR(Transactions!$A$2:$A$501)=YEAR(TODAY()))*(Transactions!$C$2:$C$501="Revenu")*Transactions!$D$2:$D$501) | E9: =SUMPRODUCT((Transactions!$A$2:$A$501<>"")*(MONTH(Transactions!$A$2:$A$501)=MONTH(TODAY()))*(YEAR(Transactions!$A$2:$A$501)=YEAR(TODAY()))*(Transactions!$C$2:$C$501="Dépense")*Transactions!$D$2:$D$501) | G9: =SUMPRODUCT((Transactions!$A$2:$A$501<>"")*(MONTH(Transactions!$A$2:$A$501)=MONTH(TODAY()))*(YEAR(Transactions!$A$2:$A$501)=YEAR(TODAY()))*(Transactions!$C$2:$C$501="Revenu")*Transactions!$D$2:$D$501)-SUMPRODUCT((Transactions!$A$2:$A$501<>"")*(MONTH(Transactions!$A$2:$A$501)=MONTH(TODAY()))*(YEAR(Transactions!$A$2:$A$501)=YEAR(TODAY()))*(Transactions!$C$2:$C$501="Dépense")*Transactions!$D$2:$D$501) | I9: =IFERROR(SUMPRODUCT((Transactions!$A$2:$A$501<>"")*(MONTH(Transactions!$A$2:$A$501)=MONTH(TODAY()))*(YEAR(Transactions!$A$2:$A$501)=YEAR(TODAY()))*(Transactions!$C$2:$C$501="Dépense")*Transactions!$D$2:$D$501)/SUMPRODUCT((Transactions!$A$2:$A$501<>"")*(MONTH(Transactions!$A$2:$A$501)=MONTH(TODAY()))*(YEAR(Transactions!$A$2:$A$501)=YEAR(TODAY()))*(Transactions!$C$2:$C$501="Revenu")*Transactions!$D$2:$D$501),0)
B10: 📊 NB TRANSACTIONS | D10: 📅 JOURS RESTANTS | F10: 📉 MOY. / JOUR | H10: 🏆 TOP CATÉGORIE
B11: =SUMPRODUCT((Transactions!$A$2:$A$501<>"")*(MONTH(Transactions!$A$2:$A$501)=MONTH(TODAY()))*(YEAR(Transactions!$A$2:$A$501)=YEAR(TODAY()))) | D11: =DAY(EOMONTH(TODAY(),0))-DAY(TODAY()) | F11: =IFERROR(SUMPRODUCT((Transactions!$A$2:$A$501<>"")*(MONTH(Transactions!$A$2:$A$501)=MONTH(TODAY()))*(YEAR(Transactions!$A$2:$A$501)=YEAR(TODAY()))*(Transactions!$C$2:$C$501="Dépense")*Transactions!$D$2:$D$501)/DAY(TODAY()),0) | H11: =IFERROR(INDEX(Paramètres!$B$4:$B$11,MATCH(MAX(SUMPRODUCT((MONTH(Transactions!$A$2:$A$501)=MONTH(TODAY()))*(YEAR(Transactions!$A$2:$A$501)=YEAR(TODAY()))*(Transactions!$C$2:$C$501="Dépense")*(Transactions!$B$2:$B$501=Paramètres!$B4)*Transactions!$D$2:$D$501)),0)),"—")
B13: ◆ BUDGET PAR CATÉGORIE — Ce mois
B14: Catégorie | C14: Budget | D14: Dépensé | E14: Restant | G14: ▓▓▓ Progression | H14: 🚦 | I14: % utilisé
B15: 🏠 Logement | C15: =Paramètres!$C$4 | D15: =SUMPRODUCT((Transactions!$A$2:$A$501<>"")*(MONTH(Transactions!$A$2:$A$501)=MONTH(TODAY()))*(YEAR(Transactions!$A$2:$A$501)=YEAR(TODAY()))*(Transactions!$B$2:$B$501="🏠 Logement")*(Transactions!$C$2:$C$501="Dépense")*Transactions!$D$2:$D$501) | E15: =C15-D15 | G15: =IF(C15=0,"—",REPT("▓",MIN(22,INT(D15/C15*22)))&REPT("░",MAX(0,22-MIN(22,INT(D15/C15*22))))) | H15: =IF(D15=0,"⬜",IF(D15/C15<0.8,"🟢",IF(D15/C15<=1,"🟡","🔴"))) | I15: =IFERROR(D15/C15,0)
B16: 🛒 Alimentation | C16: =Paramètres!$C$5 | D16: =SUMPRODUCT((Transactions!$A$2:$A$501<>"")*(MONTH(Transactions!$A$2:$A$501)=MONTH(TODAY()))*(YEAR(Transactions!$A$2:$A$501)=YEAR(TODAY()))*(Transactions!$B$2:$B$501="🛒 Alimentation")*(Transactions!$C$2:$C$501="Dépense")*Transactions!$D$2:$D$501) | E16: =C16-D16 | G16: =IF(C16=0,"—",REPT("▓",MIN(22,INT(D16/C16*22)))&REPT("░",MAX(0,22-MIN(22,INT(D16/C16*22))))) | H16: =IF(D16=0,"⬜",IF(D16/C16<0.8,"🟢",IF(D16/C16<=1,"🟡","🔴"))) | I16: =IFERROR(D16/C16,0)
B17: 🚗 Transport | C17: =Paramètres!$C$6 | D17: =SUMPRODUCT((Transactions!$A$2:$A$501<>"")*(MONTH(Transactions!$A$2:$A$501)=MONTH(TODAY()))*(YEAR(Transactions!$A$2:$A$501)=YEAR(TODAY()))*(Transactions!$B$2:$B$501="🚗 Transport")*(Transactions!$C$2:$C$501="Dépense")*Transactions!$D$2:$D$501) | E17: =C17-D17 | G17: =IF(C17=0,"—",REPT("▓",MIN(22,INT(D17/C17*22)))&REPT("░",MAX(0,22-MIN(22,INT(D17/C17*22))))) | H17: =IF(D17=0,"⬜",IF(D17/C17<0.8,"🟢",IF(D17/C17<=1,"🟡","🔴"))) | I17: =IFERROR(D17/C17,0)
B18: 💊 Santé | C18: =Paramètres!$C$7 | D18: =SUMPRODUCT((Transactions!$A$2:$A$501<>"")*(MONTH(Transactions!$A$2:$A$501)=MONTH(TODAY()))*(YEAR(Transactions!$A$2:$A$501)=YEAR(TODAY()))*(Transactions!$B$2:$B$501="💊 Santé")*(Transactions!$C$2:$C$501="Dépense")*Transactions!$D$2:$D$501) | E18: =C18-D18 | G18: =IF(C18=0,"—",REPT("▓",MIN(22,INT(D18/C18*22)))&REPT("░",MAX(0,22-MIN(22,INT(D18/C18*22))))) | H18: =IF(D18=0,"⬜",IF(D18/C18<0.8,"🟢",IF(D18/C18<=1,"🟡","🔴"))) | I18: =IFERROR(D18/C18,0)
B19: 🎮 Loisirs | C19: =Paramètres!$C$8 | D19: =SUMPRODUCT((Transactions!$A$2:$A$501<>"")*(MONTH(Transactions!$A$2:$A$501)=MONTH(TODAY()))*(YEAR(Transactions!$A$2:$A$501)=YEAR(TODAY()))*(Transactions!$B$2:$B$501="🎮 Loisirs")*(Transactions!$C$2:$C$501="Dépense")*Transactions!$D$2:$D$501) | E19: =C19-D19 | G19: =IF(C19=0,"—",REPT("▓",MIN(22,INT(D19/C19*22)))&REPT("░",MAX(0,22-MIN(22,INT(D19/C19*22))))) | H19: =IF(D19=0,"⬜",IF(D19/C19<0.8,"🟢",IF(D19/C19<=1,"🟡","🔴"))) | I19: =IFERROR(D19/C19,0)
B20: 📱 Abonnements | C20: =Paramètres!$C$9 | D20: =SUMPRODUCT((Transactions!$A$2:$A$501<>"")*(MONTH(Transactions!$A$2:$A$501)=MONTH(TODAY()))*(YEAR(Transactions!$A$2:$A$501)=YEAR(TODAY()))*(Transactions!$B$2:$B$501="📱 Abonnements")*(Transactions!$C$2:$C$501="Dépense")*Transactions!$D$2:$D$501) | E20: =C20-D20 | G20: =IF(C20=0,"—",REPT("▓",MIN(22,INT(D20/C20*22)))&REPT("░",MAX(0,22-MIN(22,INT(D20/C20*22))))) | H20: =IF(D20=0,"⬜",IF(D20/C20<0.8,"🟢",IF(D20/C20<=1,"🟡","🔴"))) | I20: =IFERROR(D20/C20,0)
B21: 👗 Shopping | C21: =Paramètres!$C$10 | D21: =SUMPRODUCT((Transactions!$A$2:$A$501<>"")*(MONTH(Transactions!$A$2:$A$501)=MONTH(TODAY()))*(YEAR(Transactions!$A$2:$A$501)=YEAR(TODAY()))*(Transactions!$B$2:$B$501="👗 Shopping")*(Transactions!$C$2:$C$501="Dépense")*Transactions!$D$2:$D$501) | E21: =C21-D21 | G21: =IF(C21=0,"—",REPT("▓",MIN(22,INT(D21/C21*22)))&REPT("░",MAX(0,22-MIN(22,INT(D21/C21*22))))) | H21: =IF(D21=0,"⬜",IF(D21/C21<0.8,"🟢",IF(D21/C21<=1,"🟡","🔴"))) | I21: =IFERROR(D21/C21,0)
B22: 💡 Divers | C22: =Paramètres!$C$11 | D22: =SUMPRODUCT((Transactions!$A$2:$A$501<>"")*(MONTH(Transactions!$A$2:$A$501)=MONTH(TODAY()))*(YEAR(Transactions!$A$2:$A$501)=YEAR(TODAY()))*(Transactions!$B$2:$B$501="💡 Divers")*(Transactions!$C$2:$C$501="Dépense")*Transactions!$D$2:$D$501) | E22: =C22-D22 | G22: =IF(C22=0,"—",REPT("▓",MIN(22,INT(D22/C22*22)))&REPT("░",MAX(0,22-MIN(22,INT(D22/C22*22))))) | H22: =IF(D22=0,"⬜",IF(D22/C22<0.8,"🟢",IF(D22/C22<=1,"🟡","🔴"))) | I22: =IFERROR(D22/C22,0)
B23: TOTAL | C23: =SUM(C15:C22) | D23: =SUM(D15:D22) | E23: =SUM(E15:E22) | G23: =IF(C23=0,"—",REPT("▓",MIN(22,INT(D23/C23*22)))&REPT("░",MAX(0,22-MIN(22,INT(D23/C23*22))))) | H23: =IF(D23=0,"⬜",IF(D23/C23<0.8,"🟢",IF(D23/C23<=1,"🟡","🔴"))) | I23: =IFERROR(D23/C23,0)
B25: ◆ ÉVOLUTION SUR 12 MOIS (année en cours)
B26: Mois | C26: Revenus | D26: Dépenses | E26: Solde | G26: ▓▓▓ Barres dépenses | H26: 📈 | I26: vs budget
B27: Janvier | C27: =SUMPRODUCT((Transactions!$A$2:$A$501<>"")*(MONTH(Transactions!$A$2:$A$501)=1)*(YEAR(Transactions!$A$2:$A$501)=YEAR(TODAY()))*(Transactions!$C$2:$C$501="Revenu")*Transactions!$D$2:$D$501) | D27: =SUMPRODUCT((Transactions!$A$2:$A$501<>"")*(MONTH(Transactions!$A$2:$A$501)=1)*(YEAR(Transactions!$A$2:$A$501)=YEAR(TODAY()))*(Transactions!$C$2:$C$501="Dépense")*Transactions!$D$2:$D$501) | E27: =C27-D27 | G27: =IF(D27=0,"—",REPT("▓",MIN(22,INT(D27/IF($J$1=0,1,$J$1)*22)))&REPT("░",MAX(0,22-MIN(22,INT(D27/IF($J$1=0,1,$J$1)*22))))) | H27: =IF(D27=0,"—",IF(D27>AVERAGE(D27:D38),"↑","↓")) | I27: =IFERROR(D27/2060,0) | J27: 🏠 Logement | K27: =SUMPRODUCT((Transactions!$A$2:$A$501<>"")*(MONTH(Transactions!$A$2:$A$501)=MONTH(TODAY()))*(YEAR(Transactions!$A$2:$A$501)=YEAR(TODAY()))*(Transactions!$B$2:$B$501="🏠 Logement")*(Transactions!$C$2:$C$501="Dépense")*Transactions!$D$2:$D$501)
B28: Février | C28: =SUMPRODUCT((Transactions!$A$2:$A$501<>"")*(MONTH(Transactions!$A$2:$A$501)=2)*(YEAR(Transactions!$A$2:$A$501)=YEAR(TODAY()))*(Transactions!$C$2:$C$501="Revenu")*Transactions!$D$2:$D$501) | D28: =SUMPRODUCT((Transactions!$A$2:$A$501<>"")*(MONTH(Transactions!$A$2:$A$501)=2)*(YEAR(Transactions!$A$2:$A$501)=YEAR(TODAY()))*(Transactions!$C$2:$C$501="Dépense")*Transactions!$D$2:$D$501) | E28: =C28-D28 | G28: =IF(D28=0,"—",REPT("▓",MIN(22,INT(D28/IF($J$1=0,1,$J$1)*22)))&REPT("░",MAX(0,22-MIN(22,INT(D28/IF($J$1=0,1,$J$1)*22))))) | H28: =IF(D28=0,"—",IF(D28>AVERAGE(D27:D38),"↑","↓")) | I28: =IFERROR(D28/2060,0) | J28: 🛒 Alimentation | K28: =SUMPRODUCT((Transactions!$A$2:$A$501<>"")*(MONTH(Transactions!$A$2:$A$501)=MONTH(TODAY()))*(YEAR(Transactions!$A$2:$A$501)=YEAR(TODAY()))*(Transactions!$B$2:$B$501="🛒 Alimentation")*(Transactions!$C$2:$C$501="Dépense")*Transactions!$D$2:$D$501)
B29: Mars | C29: =SUMPRODUCT((Transactions!$A$2:$A$501<>"")*(MONTH(Transactions!$A$2:$A$501)=3)*(YEAR(Transactions!$A$2:$A$501)=YEAR(TODAY()))*(Transactions!$C$2:$C$501="Revenu")*Transactions!$D$2:$D$501) | D29: =SUMPRODUCT((Transactions!$A$2:$A$501<>"")*(MONTH(Transactions!$A$2:$A$501)=3)*(YEAR(Transactions!$A$2:$A$501)=YEAR(TODAY()))*(Transactions!$C$2:$C$501="Dépense")*Transactions!$D$2:$D$501) | E29: =C29-D29 | G29: =IF(D29=0,"—",REPT("▓",MIN(22,INT(D29/IF($J$1=0,1,$J$1)*22)))&REPT("░",MAX(0,22-MIN(22,INT(D29/IF($J$1=0,1,$J$1)*22))))) | H29: =IF(D29=0,"—",IF(D29>AVERAGE(D27:D38),"↑","↓")) | I29: =IFERROR(D29/2060,0) | J29: 🚗 Transport | K29: =SUMPRODUCT((Transactions!$A$2:$A$501<>"")*(MONTH(Transactions!$A$2:$A$501)=MONTH(TODAY()))*(YEAR(Transactions!$A$2:$A$501)=YEAR(TODAY()))*(Transactions!$B$2:$B$501="🚗 Transport")*(Transactions!$C$2:$C$501="Dépense")*Transactions!$D$2:$D$501)
B30: Avril | C30: =SUMPRODUCT((Transactions!$A$2:$A$501<>"")*(MONTH(Transactions!$A$2:$A$501)=4)*(YEAR(Transactions!$A$2:$A$501)=YEAR(TODAY()))*(Transactions!$C$2:$C$501="Revenu")*Transactions!$D$2:$D$501) | D30: =SUMPRODUCT((Transactions!$A$2:$A$501<>"")*(MONTH(Transactions!$A$2:$A$501)=4)*(YEAR(Transactions!$A$2:$A$501)=YEAR(TODAY()))*(Transactions!$C$2:$C$501="Dépense")*Transactions!$D$2:$D$501) | E30: =C30-D30 | G30: =IF(D30=0,"—",REPT("▓",MIN(22,INT(D30/IF($J$1=0,1,$J$1)*22)))&REPT("░",MAX(0,22-MIN(22,INT(D30/IF($J$1=0,1,$J$1)*22))))) | H30: =IF(D30=0,"—",IF(D30>AVERAGE(D27:D38),"↑","↓")) | I30: =IFERROR(D30/2060,0) | J30: 💊 Santé | K30: =SUMPRODUCT((Transactions!$A$2:$A$501<>"")*(MONTH(Transactions!$A$2:$A$501)=MONTH(TODAY()))*(YEAR(Transactions!$A$2:$A$501)=YEAR(TODAY()))*(Transactions!$B$2:$B$501="💊 Santé")*(Transactions!$C$2:$C$501="Dépense")*Transactions!$D$2:$D$501)
B31: Mai | C31: =SUMPRODUCT((Transactions!$A$2:$A$501<>"")*(MONTH(Transactions!$A$2:$A$501)=5)*(YEAR(Transactions!$A$2:$A$501)=YEAR(TODAY()))*(Transactions!$C$2:$C$501="Revenu")*Transactions!$D$2:$D$501) | D31: =SUMPRODUCT((Transactions!$A$2:$A$501<>"")*(MONTH(Transactions!$A$2:$A$501)=5)*(YEAR(Transactions!$A$2:$A$501)=YEAR(TODAY()))*(Transactions!$C$2:$C$501="Dépense")*Transactions!$D$2:$D$501) | E31: =C31-D31 | G31: =IF(D31=0,"—",REPT("▓",MIN(22,INT(D31/IF($J$1=0,1,$J$1)*22)))&REPT("░",MAX(0,22-MIN(22,INT(D31/IF($J$1=0,1,$J$1)*22))))) | H31: =IF(D31=0,"—",IF(D31>AVERAGE(D27:D38),"↑","↓")) | I31: =IFERROR(D31/2060,0) | J31: 🎮 Loisirs | K31: =SUMPRODUCT((Transactions!$A$2:$A$501<>"")*(MONTH(Transactions!$A$2:$A$501)=MONTH(TODAY()))*(YEAR(Transactions!$A$2:$A$501)=YEAR(TODAY()))*(Transactions!$B$2:$B$501="🎮 Loisirs")*(Transactions!$C$2:$C$501="Dépense")*Transactions!$D$2:$D$501)
B32: Juin | C32: =SUMPRODUCT((Transactions!$A$2:$A$501<>"")*(MONTH(Transactions!$A$2:$A$501)=6)*(YEAR(Transactions!$A$2:$A$501)=YEAR(TODAY()))*(Transactions!$C$2:$C$501="Revenu")*Transactions!$D$2:$D$501) | D32: =SUMPRODUCT((Transactions!$A$2:$A$501<>"")*(MONTH(Transactions!$A$2:$A$501)=6)*(YEAR(Transactions!$A$2:$A$501)=YEAR(TODAY()))*(Transactions!$C$2:$C$501="Dépense")*Transactions!$D$2:$D$501) | E32: =C32-D32 | G32: =IF(D32=0,"—",REPT("▓",MIN(22,INT(D32/IF($J$1=0,1,$J$1)*22)))&REPT("░",MAX(0,22-MIN(22,INT(D32/IF($J$1=0,1,$J$1)*22))))) | H32: =IF(D32=0,"—",IF(D32>AVERAGE(D27:D38),"↑","↓")) | I32: =IFERROR(D32/2060,0) | J32: 📱 Abonnements | K32: =SUMPRODUCT((Transactions!$A$2:$A$501<>"")*(MONTH(Transactions!$A$2:$A$501)=MONTH(TODAY()))*(YEAR(Transactions!$A$2:$A$501)=YEAR(TODAY()))*(Transactions!$B$2:$B$501="📱 Abonnements")*(Transactions!$C$2:$C$501="Dépense")*Transactions!$D$2:$D$501)
B33: Juillet | C33: =SUMPRODUCT((Transactions!$A$2:$A$501<>"")*(MONTH(Transactions!$A$2:$A$501)=7)*(YEAR(Transactions!$A$2:$A$501)=YEAR(TODAY()))*(Transactions!$C$2:$C$501="Revenu")*Transactions!$D$2:$D$501) | D33: =SUMPRODUCT((Transactions!$A$2:$A$501<>"")*(MONTH(Transactions!$A$2:$A$501)=7)*(YEAR(Transactions!$A$2:$A$501)=YEAR(TODAY()))*(Transactions!$C$2:$C$501="Dépense")*Transactions!$D$2:$D$501) | E33: =C33-D33 | G33: =IF(D33=0,"—",REPT("▓",MIN(22,INT(D33/IF($J$1=0,1,$J$1)*22)))&REPT("░",MAX(0,22-MIN(22,INT(D33/IF($J$1=0,1,$J$1)*22))))) | H33: =IF(D33=0,"—",IF(D33>AVERAGE(D27:D38),"↑","↓")) | I33: =IFERROR(D33/2060,0) | J33: 👗 Shopping | K33: =SUMPRODUCT((Transactions!$A$2:$A$501<>"")*(MONTH(Transactions!$A$2:$A$501)=MONTH(TODAY()))*(YEAR(Transactions!$A$2:$A$501)=YEAR(TODAY()))*(Transactions!$B$2:$B$501="👗 Shopping")*(Transactions!$C$2:$C$501="Dépense")*Transactions!$D$2:$D$501)
B34: Août | C34: =SUMPRODUCT((Transactions!$A$2:$A$501<>"")*(MONTH(Transactions!$A$2:$A$501)=8)*(YEAR(Transactions!$A$2:$A$501)=YEAR(TODAY()))*(Transactions!$C$2:$C$501="Revenu")*Transactions!$D$2:$D$501) | D34: =SUMPRODUCT((Transactions!$A$2:$A$501<>"")*(MONTH(Transactions!$A$2:$A$501)=8)*(YEAR(Transactions!$A$2:$A$501)=YEAR(TODAY()))*(Transactions!$C$2:$C$501="Dépense")*Transactions!$D$2:$D$501) | E34: =C34-D34 | G34: =IF(D34=0,"—",REPT("▓",MIN(22,INT(D34/IF($J$1=0,1,$J$1)*22)))&REPT("░",MAX(0,22-MIN(22,INT(D34/IF($J$1=0,1,$J$1)*22))))) | H34: =IF(D34=0,"—",IF(D34>AVERAGE(D27:D38),"↑","↓")) | I34: =IFERROR(D34/2060,0) | J34: 💡 Divers | K34: =SUMPRODUCT((Transactions!$A$2:$A$501<>"")*(MONTH(Transactions!$A$2:$A$501)=MONTH(TODAY()))*(YEAR(Transactions!$A$2:$A$501)=YEAR(TODAY()))*(Transactions!$B$2:$B$501="💡 Divers")*(Transactions!$C$2:$C$501="Dépense")*Transactions!$D$2:$D$501)
B35: Septembre | C35: =SUMPRODUCT((Transactions!$A$2:$A$501<>"")*(MONTH(Transactions!$A$2:$A$501)=9)*(YEAR(Transactions!$A$2:$A$501)=YEAR(TODAY()))*(Transactions!$C$2:$C$501="Revenu")*Transactions!$D$2:$D$501) | D35: =SUMPRODUCT((Transactions!$A$2:$A$501<>"")*(MONTH(Transactions!$A$2:$A$501)=9)*(YEAR(Transactions!$A$2:$A$501)=YEAR(TODAY()))*(Transactions!$C$2:$C$501="Dépense")*Transactions!$D$2:$D$501) | E35: =C35-D35 | G35: =IF(D35=0,"—",REPT("▓",MIN(22,INT(D35/IF($J$1=0,1,$J$1)*22)))&REPT("░",MAX(0,22-MIN(22,INT(D35/IF($J$1=0,1,$J$1)*22))))) | H35: =IF(D35=0,"—",IF(D35>AVERAGE(D27:D38),"↑","↓")) | I35: =IFERROR(D35/2060,0)
B36: Octobre | C36: =SUMPRODUCT((Transactions!$A$2:$A$501<>"")*(MONTH(Transactions!$A$2:$A$501)=10)*(YEAR(Transactions!$A$2:$A$501)=YEAR(TODAY()))*(Transactions!$C$2:$C$501="Revenu")*Transactions!$D$2:$D$501) | D36: =SUMPRODUCT((Transactions!$A$2:$A$501<>"")*(MONTH(Transactions!$A$2:$A$501)=10)*(YEAR(Transactions!$A$2:$A$501)=YEAR(TODAY()))*(Transactions!$C$2:$C$501="Dépense")*Transactions!$D$2:$D$501) | E36: =C36-D36 | G36: =IF(D36=0,"—",REPT("▓",MIN(22,INT(D36/IF($J$1=0,1,$J$1)*22)))&REPT("░",MAX(0,22-MIN(22,INT(D36/IF($J$1=0,1,$J$1)*22))))) | H36: =IF(D36=0,"—",IF(D36>AVERAGE(D27:D38),"↑","↓")) | I36: =IFERROR(D36/2060,0)
B37: Novembre | C37: =SUMPRODUCT((Transactions!$A$2:$A$501<>"")*(MONTH(Transactions!$A$2:$A$501)=11)*(YEAR(Transactions!$A$2:$A$501)=YEAR(TODAY()))*(Transactions!$C$2:$C$501="Revenu")*Transactions!$D$2:$D$501) | D37: =SUMPRODUCT((Transactions!$A$2:$A$501<>"")*(MONTH(Transactions!$A$2:$A$501)=11)*(YEAR(Transactions!$A$2:$A$501)=YEAR(TODAY()))*(Transactions!$C$2:$C$501="Dépense")*Transactions!$D$2:$D$501) | E37: =C37-D37 | G37: =IF(D37=0,"—",REPT("▓",MIN(22,INT(D37/IF($J$1=0,1,$J$1)*22)))&REPT("░",MAX(0,22-MIN(22,INT(D37/IF($J$1=0,1,$J$1)*22))))) | H37: =IF(D37=0,"—",IF(D37>AVERAGE(D27:D38),"↑","↓")) | I37: =IFERROR(D37/2060,0)
B38: Décembre | C38: =SUMPRODUCT((Transactions!$A$2:$A$501<>"")*(MONTH(Transactions!$A$2:$A$501)=12)*(YEAR(Transactions!$A$2:$A$501)=YEAR(TODAY()))*(Transactions!$C$2:$C$501="Revenu")*Transactions!$D$2:$D$501) | D38: =SUMPRODUCT((Transactions!$A$2:$A$501<>"")*(MONTH(Transactions!$A$2:$A$501)=12)*(YEAR(Transactions!$A$2:$A$501)=YEAR(TODAY()))*(Transactions!$C$2:$C$501="Dépense")*Transactions!$D$2:$D$501) | E38: =C38-D38 | G38: =IF(D38=0,"—",REPT("▓",MIN(22,INT(D38/IF($J$1=0,1,$J$1)*22)))&REPT("░",MAX(0,22-MIN(22,INT(D38/IF($J$1=0,1,$J$1)*22))))) | H38: =IF(D38=0,"—",IF(D38>AVERAGE(D27:D38),"↑","↓")) | I38: =IFERROR(D38/2060,0)
B58: ◆ 10 DERNIÈRES TRANSACTIONS (auto-actualisé)
B59: Date | C59: Catégorie | D59: Type | E59: Montant | F59: Note
B60: =IFERROR(INDEX(Transactions!$A:$A,IFERROR(COUNTA(Transactions!$B$5:$B$500)-9+4,1)),"") | C60: =IFERROR(INDEX(Transactions!$B:$B,IFERROR(COUNTA(Transactions!$B$5:$B$500)-9+4,1)),"") | D60: =IFERROR(INDEX(Transactions!$C:$C,IFERROR(COUNTA(Transactions!$B$5:$B$500)-9+4,1)),"") | E60: =IFERROR(INDEX(Transactions!$D:$D,IFERROR(COUNTA(Transactions!$B$5:$B$500)-9+4,1)),"") | F60: =IFERROR(INDEX(Transactions!$E:$E,IFERROR(COUNTA(Transactions!$B$5:$B$500)-9+4,1)),"")
B61: =IFERROR(INDEX(Transactions!$A:$A,IFERROR(COUNTA(Transactions!$B$5:$B$500)-8+4,1)),"") | C61: =IFERROR(INDEX(Transactions!$B:$B,IFERROR(COUNTA(Transactions!$B$5:$B$500)-8+4,1)),"") | D61: =IFERROR(INDEX(Transactions!$C:$C,IFERROR(COUNTA(Transactions!$B$5:$B$500)-8+4,1)),"") | E61: =IFERROR(INDEX(Transactions!$D:$D,IFERROR(COUNTA(Transactions!$B$5:$B$500)-8+4,1)),"") | F61: =IFERROR(INDEX(Transactions!$E:$E,IFERROR(COUNTA(Transactions!$B$5:$B$500)-8+4,1)),"")
B62: =IFERROR(INDEX(Transactions!$A:$A,IFERROR(COUNTA(Transactions!$B$5:$B$500)-7+4,1)),"") | C62: =IFERROR(INDEX(Transactions!$B:$B,IFERROR(COUNTA(Transactions!$B$5:$B$500)-7+4,1)),"") | D62: =IFERROR(INDEX(Transactions!$C:$C,IFERROR(COUNTA(Transactions!$B$5:$B$500)-7+4,1)),"") | E62: =IFERROR(INDEX(Transactions!$D:$D,IFERROR(COUNTA(Transactions!$B$5:$B$500)-7+4,1)),"") | F62: =IFERROR(INDEX(Transactions!$E:$E,IFERROR(COUNTA(Transactions!$B$5:$B$500)-7+4,1)),"")
B63: =IFERROR(INDEX(Transactions!$A:$A,IFERROR(COUNTA(Transactions!$B$5:$B$500)-6+4,1)),"") | C63: =IFERROR(INDEX(Transactions!$B:$B,IFERROR(COUNTA(Transactions!$B$5:$B$500)-6+4,1)),"") | D63: =IFERROR(INDEX(Transactions!$C:$C,IFERROR(COUNTA(Transactions!$B$5:$B$500)-6+4,1)),"") | E63: =IFERROR(INDEX(Transactions!$D:$D,IFERROR(COUNTA(Transactions!$B$5:$B$500)-6+4,1)),"") | F63: =IFERROR(INDEX(Transactions!$E:$E,IFERROR(COUNTA(Transactions!$B$5:$B$500)-6+4,1)),"")
B64: =IFERROR(INDEX(Transactions!$A:$A,IFERROR(COUNTA(Transactions!$B$5:$B$500)-5+4,1)),"") | C64: =IFERROR(INDEX(Transactions!$B:$B,IFERROR(COUNTA(Transactions!$B$5:$B$500)-5+4,1)),"") | D64: =IFERROR(INDEX(Transactions!$C:$C,IFERROR(COUNTA(Transactions!$B$5:$B$500)-5+4,1)),"") | E64: =IFERROR(INDEX(Transactions!$D:$D,IFERROR(COUNTA(Transactions!$B$5:$B$500)-5+4,1)),"") | F64: =IFERROR(INDEX(Transactions!$E:$E,IFERROR(COUNTA(Transactions!$B$5:$B$500)-5+4,1)),"")
...

Sheet 📝 Transactions
B2: 📝 TRANSACTIONS — Saisissez chaque opération ici
B3: ✦ Entrez Date · Catégorie · Type (Dépense / Revenu) · Montant · Note — Le Dashboard se met à jour automatiquement
B4: Date | C4: Catégorie | D4: Type | E4: Montant | F4: Note
B5: 46113 | C5: 🏠 Logement | D5: Dépense | E5: 900 | F5: Loyer
B6: 46115 | C6: 👗 Shopping | D6: Dépense | E6: 9.19 | F6: Zara
B7: 46115 | C7: 🛒 Alimentation | D7: Dépense | E7: 62.43 | F7: Amazon Fresh
B8: 46116 | C8: 🏠 Logement | D8: Dépense | E8: 35.43 | F8: Assurance habitation
B9: 46116 | C9: 👗 Shopping | D9: Dépense | E9: 30.08 | F9: Zara
B10: 46117 | C10: 📱 Abonnements | D10: Dépense | E10: 10 | F10: Spotify
B11: 46117 | C11: 📱 Abonnements | D11: Dépense | E11: 14 | F11: Netflix
B12: 46117 | C12: 📱 Abonnements | D12: Dépense | E12: 3 | F12: iCloud 200 Go
B13: 46117 | C13: 📱 Abonnements | D13: Dépense | E13: 35 | F13: Canal+
B14: 46118 | C14: 🎮 Loisirs | D14: Dépense | E14: 53.37 | F14: Jeux vidéo Steam
B15: 46121 | C15: 🚗 Transport | D15: Dépense | E15: 73.71 | F15: Contrôle technique
B16: 46122 | C16: 💊 Santé | D16: Dépense | E16: 19.97 | F16: Médecin généraliste
... B67: 46189 | C67: 📱 Abonnements | D67: Dépense | E67: 16.23 | F67: Spotify

Sheet ⚙️ Paramètres
B2: ⚙️ PARAMÈTRES — Catégories & Budgets mensuels
B3: Catégorie dépense | C3: Budget mensuel | E3: 📌 Comment personnaliser
B4: 🏠 Logement | C4: 900 | E4: Modifiez les budgets colonne C.
B5: 🛒 Alimentation | C5: 450 | E5: Ajoutez des catégories sous la ligne 11.
B6: 🚗 Transport | C6: 200 | E6: Mettez à jour le menu déroulant dans
B7: 💊 Santé | C7: 100 | E7: l'onglet Transactions si vous changez
B8: 🎮 Loisirs | C8: 150 | E8: les catégories (plage Paramètres!B2:B9).
B9: 📱 Abonnements | C9: 60
B10: 👗 Shopping | C10: 120
B11: 💡 Divers | C11: 80
B14: Types de transactions
B15: Dépense
B16: Revenu
