Workbook

Sheet Dashboard
B2: 💰 WEEKLY EXPENSE PLANNER — Vue d'ensemble annuelle
B3: Toutes les données ci-dessous sont automatiques
B5: 📊 INDICATEURS CLÉS ANNUELS
B7: 💸 Total dépensé annuel | E7: 📅 Budget annuel total | H7: 💚 Économies estimées
B8: =Janvier!C12+Fevrier!C12+Mars!C12+Avril!C12+Mai!C12+Juin!C12+Juillet!C12+Aout!C12+Septembre!C12+Octobre!C12+Novembre!C12+Decembre!C12 | E8: =Janvier!D12+Fevrier!D12+Mars!D12+Avril!D12+Mai!D12+Juin!D12+Juillet!D12+Aout!D12+Septembre!D12+Octobre!D12+Novembre!D12+Decembre!D12 | H8: =Janvier!D12+Fevrier!D12+Mars!D12+Avril!D12+Mai!D12+Juin!D12+Juillet!D12+Aout!D12+Septembre!D12+Octobre!D12+Novembre!D12+Decembre!D12-(Janvier!C12+Fevrier!C12+Mars!C12+Avril!C12+Mai!C12+Juin!C12+Juillet!C12+Aout!C12+Septembre!C12+Octobre!C12+Novembre!C12+Decembre!C12)
B10: 📉 % Budget consommé | E10: 📆 Semaines saisies | H10: 🔢 Moy. / semaine
B11: =IFERROR((Janvier!C12+Fevrier!C12+Mars!C12+Avril!C12+Mai!C12+Juin!C12+Juillet!C12+Aout!C12+Septembre!C12+Octobre!C12+Novembre!C12+Decembre!C12)/(Janvier!D12+Fevrier!D12+Mars!D12+Avril!D12+Mai!D12+Juin!D12+Juillet!D12+Aout!D12+Septembre!D12+Octobre!D12+Novembre!D12+Decembre!D12),0) | E11: =COUNTA(S01:S52!J12)-COUNTIF(S01:S52!J12,0) | H11: =IFERROR((Janvier!C12+Fevrier!C12+Mars!C12+Avril!C12+Mai!C12+Juin!C12+Juillet!C12+Aout!C12+Septembre!C12+Octobre!C12+Novembre!C12+Decembre!C12)/52,0)
B13: 📈 DÉPENSES PAR MOIS (automatique)
B30: Mois | C30: Dépensé | D30: Budget
B31: Jan | C31: ='Janvier'!C12 | D31: ='Janvier'!D12
B32: Fév | C32: ='Fevrier'!C12 | D32: ='Fevrier'!D12
B33: Mar | C33: ='Mars'!C12 | D33: ='Mars'!D12
B34: Avr | C34: ='Avril'!C12 | D34: ='Avril'!D12
B35: Mai | C35: ='Mai'!C12 | D35: ='Mai'!D12
B36: Jun | C36: ='Juin'!C12 | D36: ='Juin'!D12
B37: Jul | C37: ='Juillet'!C12 | D37: ='Juillet'!D12
B38: Aoû | C38: ='Aout'!C12 | D38: ='Aout'!D12
B39: Sep | C39: ='Septembre'!C12 | D39: ='Septembre'!D12
B40: Oct | C40: ='Octobre'!C12 | D40: ='Octobre'!D12
B41: Nov | C41: ='Novembre'!C12 | D41: ='Novembre'!D12
B42: Déc | C42: ='Decembre'!C12 | D42: ='Decembre'!D12

Sheet Janvier
B2: 📅 JANVIER — Récapitulatif mensuel (semaines 01–04)
B3: Catégorie | C3: Total dépensé | D3: Budget mensuel | E3: Restant | F3: % utilisé | G3: ▓▓▓ Progression | H3: 🚦
B4: 🏠 Logement | C4: =S01!J4+S02!J4+S03!J4+S04!J4 | D4: =S01!K4+S02!K4+S03!K4+S04!K4 | E4: =D4-C4 | F4: =IF(D4=0,0,C4/D4) | G4: =IF(D4=0,"—",REPT("▓",MIN(20,INT(C4/D4*20)))&REPT("░",MAX(0,20-MIN(20,INT(C4/D4*20))))) | H4: =IF(C4=0,"⬜",IF(C4/D4<0.8,"🟢",IF(C4/D4<=1,"🟡","🔴")))
B5: 🛒 Alimentation | C5: =S01!J5+S02!J5+S03!J5+S04!J5 | D5: =S01!K5+S02!K5+S03!K5+S04!K5 | E5: =D5-C5 | F5: =IF(D5=0,0,C5/D5) | G5: =IF(D5=0,"—",REPT("▓",MIN(20,INT(C5/D5*20)))&REPT("░",MAX(0,20-MIN(20,INT(C5/D5*20))))) | H5: =IF(C5=0,"⬜",IF(C5/D5<0.8,"🟢",IF(C5/D5<=1,"🟡","🔴")))
B6: 🚗 Transport | C6: =S01!J6+S02!J6+S03!J6+S04!J6 | D6: =S01!K6+S02!K6+S03!K6+S04!K6 | E6: =D6-C6 | F6: =IF(D6=0,0,C6/D6) | G6: =IF(D6=0,"—",REPT("▓",MIN(20,INT(C6/D6*20)))&REPT("░",MAX(0,20-MIN(20,INT(C6/D6*20))))) | H6: =IF(C6=0,"⬜",IF(C6/D6<0.8,"🟢",IF(C6/D6<=1,"🟡","🔴")))
B7: 💊 Santé | C7: =S01!J7+S02!J7+S03!J7+S04!J7 | D7: =S01!K7+S02!K7+S03!K7+S04!K7 | E7: =D7-C7 | F7: =IF(D7=0,0,C7/D7) | G7: =IF(D7=0,"—",REPT("▓",MIN(20,INT(C7/D7*20)))&REPT("░",MAX(0,20-MIN(20,INT(C7/D7*20))))) | H7: =IF(C7=0,"⬜",IF(C7/D7<0.8,"🟢",IF(C7/D7<=1,"🟡","🔴")))
B8: 🎮 Loisirs | C8: =S01!J8+S02!J8+S03!J8+S04!J8 | D8: =S01!K8+S02!K8+S03!K8+S04!K8 | E8: =D8-C8 | F8: =IF(D8=0,0,C8/D8) | G8: =IF(D8=0,"—",REPT("▓",MIN(20,INT(C8/D8*20)))&REPT("░",MAX(0,20-MIN(20,INT(C8/D8*20))))) | H8: =IF(C8=0,"⬜",IF(C8/D8<0.8,"🟢",IF(C8/D8<=1,"🟡","🔴")))
B9: 📱 Abonnements | C9: =S01!J9+S02!J9+S03!J9+S04!J9 | D9: =S01!K9+S02!K9+S03!K9+S04!K9 | E9: =D9-C9 | F9: =IF(D9=0,0,C9/D9) | G9: =IF(D9=0,"—",REPT("▓",MIN(20,INT(C9/D9*20)))&REPT("░",MAX(0,20-MIN(20,INT(C9/D9*20))))) | H9: =IF(C9=0,"⬜",IF(C9/D9<0.8,"🟢",IF(C9/D9<=1,"🟡","🔴")))
B10: 👗 Shopping | C10: =S01!J10+S02!J10+S03!J10+S04!J10 | D10: =S01!K10+S02!K10+S03!K10+S04!K10 | E10: =D10-C10 | F10: =IF(D10=0,0,C10/D10) | G10: =IF(D10=0,"—",REPT("▓",MIN(20,INT(C10/D10*20)))&REPT("░",MAX(0,20-MIN(20,INT(C10/D10*20))))) | H10: =IF(C10=0,"⬜",IF(C10/D10<0.8,"🟢",IF(C10/D10<=1,"🟡","🔴")))
B11: 💡 Divers | C11: =S01!J11+S02!J11+S03!J11+S04!J11 | D11: =S01!K11+S02!K11+S03!K11+S04!K11 | E11: =D11-C11 | F11: =IF(D11=0,0,C11/D11) | G11: =IF(D11=0,"—",REPT("▓",MIN(20,INT(C11/D11*20)))&REPT("░",MAX(0,20-MIN(20,INT(C11/D11*20))))) | H11: =IF(C11=0,"⬜",IF(C11/D11<0.8,"🟢",IF(C11/D11<=1,"🟡","🔴")))
B12: TOTAL MENSUEL | C12: =SUM(C4:C11) | D12: =SUM(D4:D11) | E12: =SUM(E4:E11) | F12: =IF(D12=0,0,C12/D12) | G12: =IF(D12=0,"—",REPT("▓",MIN(20,INT(C12/D12*20)))&REPT("░",MAX(0,20-MIN(20,INT(C12/D12*20))))) | H12: =IF(C12=0,"⬜",IF(C12/D12<0.8,"🟢",IF(C12/D12<=1,"🟡","🔴")))

Sheet Fevrier
B2: 📅 FÉVRIER — Récapitulatif mensuel (semaines 05–08)
B3: Catégorie | C3: Total dépensé | D3: Budget mensuel | E3: Restant | F3: % utilisé | G3: ▓▓▓ Progression | H3: 🚦
B4: 🏠 Logement | C4: =S05!J4+S06!J4+S07!J4+S08!J4 | D4: =S05!K4+S06!K4+S07!K4+S08!K4 | E4: =D4-C4 | F4: =IF(D4=0,0,C4/D4) | G4: =IF(D4=0,"—",REPT("▓",MIN(20,INT(C4/D4*20)))&REPT("░",MAX(0,20-MIN(20,INT(C4/D4*20))))) | H4: =IF(C4=0,"⬜",IF(C4/D4<0.8,"🟢",IF(C4/D4<=1,"🟡","🔴")))
B5: 🛒 Alimentation | C5: =S05!J5+S06!J5+S07!J5+S08!J5 | D5: =S05!K5+S06!K5+S07!K5+S08!K5 | E5: =D5-C5 | F5: =IF(D5=0,0,C5/D5) | G5: =IF(D5=0,"—",REPT("▓",MIN(20,INT(C5/D5*20)))&REPT("░",MAX(0,20-MIN(20,INT(C5/D5*20))))) | H5: =IF(C5=0,"⬜",IF(C5/D5<0.8,"🟢",IF(C5/D5<=1,"🟡","🔴")))
B6: 🚗 Transport | C6: =S05!J6+S06!J6+S07!J6+S08!J6 | D6: =S05!K6+S06!K6+S07!K6+S08!K6 | E6: =D6-C6 | F6: =IF(D6=0,0,C6/D6) | G6: =IF(D6=0,"—",REPT("▓",MIN(20,INT(C6/D6*20)))&REPT("░",MAX(0,20-MIN(20,INT(C6/D6*20))))) | H6: =IF(C6=0,"⬜",IF(C6/D6<0.8,"🟢",IF(C6/D6<=1,"🟡","🔴")))
B7: 💊 Santé | C7: =S05!J7+S06!J7+S07!J7+S08!J7 | D7: =S05!K7+S06!K7+S07!K7+S08!K7 | E7: =D7-C7 | F7: =IF(D7=0,0,C7/D7) | G7: =IF(D7=0,"—",REPT("▓",MIN(20,INT(C7/D7*20)))&REPT("░",MAX(0,20-MIN(20,INT(C7/D7*20))))) | H7: =IF(C7=0,"⬜",IF(C7/D7<0.8,"🟢",IF(C7/D7<=1,"🟡","🔴")))
B8: 🎮 Loisirs | C8: =S05!J8+S06!J8+S07!J8+S08!J8 | D8: =S05!K8+S06!K8+S07!K8+S08!K8 | E8: =D8-C8 | F8: =IF(D8=0,0,C8/D8) | G8: =IF(D8=0,"—",REPT("▓",MIN(20,INT(C8/D8*20)))&REPT("░",MAX(0,20-MIN(20,INT(C8/D8*20))))) | H8: =IF(C8=0,"⬜",IF(C8/D8<0.8,"🟢",IF(C8/D8<=1,"🟡","🔴")))
B9: 📱 Abonnements | C9: =S05!J9+S06!J9+S07!J9+S08!J9 | D9: =S05!K9+S06!K9+S07!K9+S08!K9 | E9: =D9-C9 | F9: =IF(D9=0,0,C9/D9) | G9: =IF(D9=0,"—",REPT("▓",MIN(20,INT(C9/D9*20)))&REPT("░",MAX(0,20-MIN(20,INT(C9/D9*20))))) | H9: =IF(C9=0,"⬜",IF(C9/D9<0.8,"🟢",IF(C9/D9<=1,"🟡","🔴")))
B10: 👗 Shopping | C10: =S05!J10+S06!J10+S07!J10+S08!J10 | D10: =S05!K10+S06!K10+S07!K10+S08!K10 | E10: =D10-C10 | F10: =IF(D10=0,0,C10/D10) | G10: =IF(D10=0,"—",REPT("▓",MIN(20,INT(C10/D10*20)))&REPT("░",MAX(0,20-MIN(20,INT(C10/D10*20))))) | H10: =IF(C10=0,"⬜",IF(C10/D10<0.8,"🟢",IF(C10/D10<=1,"🟡","🔴")))
B11: 💡 Divers | C11: =S05!J11+S06!J11+S07!J11+S08!J11 | D11: =S05!K11+S06!K11+S07!K11+S08!K11 | E11: =D11-C11 | F11: =IF(D11=0,0,C11/D11) | G11: =IF(D11=0,"—",REPT("▓",MIN(20,INT(C11/D11*20)))&REPT("░",MAX(0,20-MIN(20,INT(C11/D11*20))))) | H11: =IF(C11=0,"⬜",IF(C11/D11<0.8,"🟢",IF(C11/D11<=1,"🟡","🔴")))
B12: TOTAL MENSUEL | C12: =SUM(C4:C11) | D12: =SUM(D4:D11) | E12: =SUM(E4:E11) | F12: =IF(D12=0,0,C12/D12) | G12: =IF(D12=0,"—",REPT("▓",MIN(20,INT(C12/D12*20)))&REPT("░",MAX(0,20-MIN(20,INT(C12/D12*20))))) | H12: =IF(C12=0,"⬜",IF(C12/D12<0.8,"🟢",IF(C12/D12<=1,"🟡","🔴")))

Sheet Mars
B2: 📅 MARS — Récapitulatif mensuel (semaines 09–13)
B3: Catégorie | C3: Total dépensé | D3: Budget mensuel | E3: Restant | F3: % utilisé | G3: ▓▓▓ Progression | H3: 🚦
B4: 🏠 Logement | C4: =S09!J4+S10!J4+S11!J4+S12!J4+S13!J4 | D4: =S09!K4+S10!K4+S11!K4+S12!K4+S13!K4 | E4: =D4-C4 | F4: =IF(D4=0,0,C4/D4) | G4: =IF(D4=0,"—",REPT("▓",MIN(20,INT(C4/D4*20)))&REPT("░",MAX(0,20-MIN(20,INT(C4/D4*20))))) | H4: =IF(C4=0,"⬜",IF(C4/D4<0.8,"🟢",IF(C4/D4<=1,"🟡","🔴")))
B5: 🛒 Alimentation | C5: =S09!J5+S10!J5+S11!J5+S12!J5+S13!J5 | D5: =S09!K5+S10!K5+S11!K5+S12!K5+S13!K5 | E5: =D5-C5 | F5: =IF(D5=0,0,C5/D5) | G5: =IF(D5=0,"—",REPT("▓",MIN(20,INT(C5/D5*20)))&REPT("░",MAX(0,20-MIN(20,INT(C5/D5*20))))) | H5: =IF(C5=0,"⬜",IF(C5/D5<0.8,"🟢",IF(C5/D5<=1,"🟡","🔴")))
B6: 🚗 Transport | C6: =S09!J6+S10!J6+S11!J6+S12!J6+S13!J6 | D6: =S09!K6+S10!K6+S11!K6+S12!K6+S13!K6 | E6: =D6-C6 | F6: =IF(D6=0,0,C6/D6) | G6: =IF(D6=0,"—",REPT("▓",MIN(20,INT(C6/D6*20)))&REPT("░",MAX(0,20-MIN(20,INT(C6/D6*20))))) | H6: =IF(C6=0,"⬜",IF(C6/D6<0.8,"🟢",IF(C6/D6<=1,"🟡","🔴")))
B7: 💊 Santé | C7: =S09!J7+S10!J7+S11!J7+S12!J7+S13!J7 | D7: =S09!K7+S10!K7+S11!K7+S12!K7+S13!K7 | E7: =D7-C7 | F7: =IF(D7=0,0,C7/D7) | G7: =IF(D7=0,"—",REPT("▓",MIN(20,INT(C7/D7*20)))&REPT("░",MAX(0,20-MIN(20,INT(C7/D7*20))))) | H7: =IF(C7=0,"⬜",IF(C7/D7<0.8,"🟢",IF(C7/D7<=1,"🟡","🔴")))
B8: 🎮 Loisirs | C8: =S09!J8+S10!J8+S11!J8+S12!J8+S13!J8 | D8: =S09!K8+S10!K8+S11!K8+S12!K8+S13!K8 | E8: =D8-C8 | F8: =IF(D8=0,0,C8/D8) | G8: =IF(D8=0,"—",REPT("▓",MIN(20,INT(C8/D8*20)))&REPT("░",MAX(0,20-MIN(20,INT(C8/D8*20))))) | H8: =IF(C8=0,"⬜",IF(C8/D8<0.8,"🟢",IF(C8/D8<=1,"🟡","🔴")))
B9: 📱 Abonnements | C9: =S09!J9+S10!J9+S11!J9+S12!J9+S13!J9 | D9: =S09!K9+S10!K9+S11!K9+S12!K9+S13!K9 | E9: =D9-C9 | F9: =IF(D9=0,0,C9/D9) | G9: =IF(D9=0,"—",REPT("▓",MIN(20,INT(C9/D9*20)))&REPT("░",MAX(0,20-MIN(20,INT(C9/D9*20))))) | H9: =IF(C9=0,"⬜",IF(C9/D9<0.8,"🟢",IF(C9/D9<=1,"🟡","🔴")))
B10: 👗 Shopping | C10: =S09!J10+S10!J10+S11!J10+S12!J10+S13!J10 | D10: =S09!K10+S10!K10+S11!K10+S12!K10+S13!K10 | E10: =D10-C10 | F10: =IF(D10=0,0,C10/D10) | G10: =IF(D10=0,"—",REPT("▓",MIN(20,INT(C10/D10*20)))&REPT("░",MAX(0,20-MIN(20,INT(C10/D10*20))))) | H10: =IF(C10=0,"⬜",IF(C10/D10<0.8,"🟢",IF(C10/D10<=1,"🟡","🔴")))
B11: 💡 Divers | C11: =S09!J11+S10!J11+S11!J11+S12!J11+S13!J11 | D11: =S09!K11+S10!K11+S11!K11+S12!K11+S13!K11 | E11: =D11-C11 | F11: =IF(D11=0,0,C11/D11) | G11: =IF(D11=0,"—",REPT("▓",MIN(20,INT(C11/D11*20)))&REPT("░",MAX(0,20-MIN(20,INT(C11/D11*20))))) | H11: =IF(C11=0,"⬜",IF(C11/D11<0.8,"🟢",IF(C11/D11<=1,"🟡","🔴")))
B12: TOTAL MENSUEL | C12: =SUM(C4:C11) | D12: =SUM(D4:D11) | E12: =SUM(E4:E11) | F12: =IF(D12=0,0,C12/D12) | G12: =IF(D12=0,"—",REPT("▓",MIN(20,INT(C12/D12*20)))&REPT("░",MAX(0,20-MIN(20,INT(C12/D12*20))))) | H12: =IF(C12=0,"⬜",IF(C12/D12<0.8,"🟢",IF(C12/D12<=1,"🟡","🔴")))

Sheet Avril
B2: 📅 AVRIL — Récapitulatif mensuel (semaines 14–17)
B3: Catégorie | C3: Total dépensé | D3: Budget mensuel | E3: Restant | F3: % utilisé | G3: ▓▓▓ Progression | H3: 🚦
B4: 🏠 Logement | C4: =S14!J4+S15!J4+S16!J4+S17!J4 | D4: =S14!K4+S15!K4+S16!K4+S17!K4 | E4: =D4-C4 | F4: =IF(D4=0,0,C4/D4) | G4: =IF(D4=0,"—",REPT("▓",MIN(20,INT(C4/D4*20)))&REPT("░",MAX(0,20-MIN(20,INT(C4/D4*20))))) | H4: =IF(C4=0,"⬜",IF(C4/D4<0.8,"🟢",IF(C4/D4<=1,"🟡","🔴")))
B5: 🛒 Alimentation | C5: =S14!J5+S15!J5+S16!J5+S17!J5 | D5: =S14!K5+S15!K5+S16!K5+S17!K5 | E5: =D5-C5 | F5: =IF(D5=0,0,C5/D5) | G5: =IF(D5=0,"—",REPT("▓",MIN(20,INT(C5/D5*20)))&REPT("░",MAX(0,20-MIN(20,INT(C5/D5*20))))) | H5: =IF(C5=0,"⬜",IF(C5/D5<0.8,"🟢",IF(C5/D5<=1,"🟡","🔴")))
B6: 🚗 Transport | C6: =S14!J6+S15!J6+S16!J6+S17!J6 | D6: =S14!K6+S15!K6+S16!K6+S17!K6 | E6: =D6-C6 | F6: =IF(D6=0,0,C6/D6) | G6: =IF(D6=0,"—",REPT("▓",MIN(20,INT(C6/D6*20)))&REPT("░",MAX(0,20-MIN(20,INT(C6/D6*20))))) | H6: =IF(C6=0,"⬜",IF(C6/D6<0.8,"🟢",IF(C6/D6<=1,"🟡","🔴")))
B7: 💊 Santé | C7: =S14!J7+S15!J7+S16!J7+S17!J7 | D7: =S14!K7+S15!K7+S16!K7+S17!K7 | E7: =D7-C7 | F7: =IF(D7=0,0,C7/D7) | G7: =IF(D7=0,"—",REPT("▓",MIN(20,INT(C7/D7*20)))&REPT("░",MAX(0,20-MIN(20,INT(C7/D7*20))))) | H7: =IF(C7=0,"⬜",IF(C7/D7<0.8,"🟢",IF(C7/D7<=1,"🟡","🔴")))
B8: 🎮 Loisirs | C8: =S14!J8+S15!J8+S16!J8+S17!J8 | D8: =S14!K8+S15!K8+S16!K8+S17!K8 | E8: =D8-C8 | F8: =IF(D8=0,0,C8/D8) | G8: =IF(D8=0,"—",REPT("▓",MIN(20,INT(C8/D8*20)))&REPT("░",MAX(0,20-MIN(20,INT(C8/D8*20))))) | H8: =IF(C8=0,"⬜",IF(C8/D8<0.8,"🟢",IF(C8/D8<=1,"🟡","🔴")))
B9: 📱 Abonnements | C9: =S14!J9+S15!J9+S16!J9+S17!J9 | D9: =S14!K9+S15!K9+S16!K9+S17!K9 | E9: =D9-C9 | F9: =IF(D9=0,0,C9/D9) | G9: =IF(D9=0,"—",REPT("▓",MIN(20,INT(C9/D9*20)))&REPT("░",MAX(0,20-MIN(20,INT(C9/D9*20))))) | H9: =IF(C9=0,"⬜",IF(C9/D9<0.8,"🟢",IF(C9/D9<=1,"🟡","🔴")))
B10: 👗 Shopping | C10: =S14!J10+S15!J10+S16!J10+S17!J10 | D10: =S14!K10+S15!K10+S16!K10+S17!K10 | E10: =D10-C10 | F10: =IF(D10=0,0,C10/D10) | G10: =IF(D10=0,"—",REPT("▓",MIN(20,INT(C10/D10*20)))&REPT("░",MAX(0,20-MIN(20,INT(C10/D10*20))))) | H10: =IF(C10=0,"⬜",IF(C10/D10<0.8,"🟢",IF(C10/D10<=1,"🟡","🔴")))
B11: 💡 Divers | C11: =S14!J11+S15!J11+S16!J11+S17!J11 | D11: =S14!K11+S15!K11+S16!K11+S17!K11 | E11: =D11-C11 | F11: =IF(D11=0,0,C11/D11) | G11: =IF(D11=0,"—",REPT("▓",MIN(20,INT(C11/D11*20)))&REPT("░",MAX(0,20-MIN(20,INT(C11/D11*20))))) | H11: =IF(C11=0,"⬜",IF(C11/D11<0.8,"🟢",IF(C11/D11<=1,"🟡","🔴")))
B12: TOTAL MENSUEL | C12: =SUM(C4:C11) | D12: =SUM(D4:D11) | E12: =SUM(E4:E11) | F12: =IF(D12=0,0,C12/D12) | G12: =IF(D12=0,"—",REPT("▓",MIN(20,INT(C12/D12*20)))&REPT("░",MAX(0,20-MIN(20,INT(C12/D12*20))))) | H12: =IF(C12=0,"⬜",IF(C12/D12<0.8,"🟢",IF(C12/D12<=1,"🟡","🔴")))

Sheet Mai
B2: 📅 MAI — Récapitulatif mensuel (semaines 18–21)
B3: Catégorie | C3: Total dépensé | D3: Budget mensuel | E3: Restant | F3: % utilisé | G3: ▓▓▓ Progression | H3: 🚦
B4: 🏠 Logement | C4: =S18!J4+S19!J4+S20!J4+S21!J4 | D4: =S18!K4+S19!K4+S20!K4+S21!K4 | E4: =D4-C4 | F4: =IF(D4=0,0,C4/D4) | G4: =IF(D4=0,"—",REPT("▓",MIN(20,INT(C4/D4*20)))&REPT("░",MAX(0,20-MIN(20,INT(C4/D4*20))))) | H4: =IF(C4=0,"⬜",IF(C4/D4<0.8,"🟢",IF(C4/D4<=1,"🟡","🔴")))
B5: 🛒 Alimentation | C5: =S18!J5+S19!J5+S20!J5+S21!J5 | D5: =S18!K5+S19!K5+S20!K5+S21!K5 | E5: =D5-C5 | F5: =IF(D5=0,0,C5/D5) | G5: =IF(D5=0,"—",REPT("▓",MIN(20,INT(C5/D5*20)))&REPT("░",MAX(0,20-MIN(20,INT(C5/D5*20))))) | H5: =IF(C5=0,"⬜",IF(C5/D5<0.8,"🟢",IF(C5/D5<=1,"🟡","🔴")))
B6: 🚗 Transport | C6: =S18!J6+S19!J6+S20!J6+S21!J6 | D6: =S18!K6+S19!K6+S20!K6+S21!K6 | E6: =D6-C6 | F6: =IF(D6=0,0,C6/D6) | G6: =IF(D6=0,"—",REPT("▓",MIN(20,INT(C6/D6*20)))&REPT("░",MAX(0,20-MIN(20,INT(C6/D6*20))))) | H6: =IF(C6=0,"⬜",IF(C6/D6<0.8,"🟢",IF(C6/D6<=1,"🟡","🔴")))
B7: 💊 Santé | C7: =S18!J7+S19!J7+S20!J7+S21!J7 | D7: =S18!K7+S19!K7+S20!K7+S21!K7 | E7: =D7-C7 | F7: =IF(D7=0,0,C7/D7) | G7: =IF(D7=0,"—",REPT("▓",MIN(20,INT(C7/D7*20)))&REPT("░",MAX(0,20-MIN(20,INT(C7/D7*20))))) | H7: =IF(C7=0,"⬜",IF(C7/D7<0.8,"🟢",IF(C7/D7<=1,"🟡","🔴")))
B8: 🎮 Loisirs | C8: =S18!J8+S19!J8+S20!J8+S21!J8 | D8: =S18!K8+S19!K8+S20!K8+S21!K8 | E8: =D8-C8 | F8: =IF(D8=0,0,C8/D8) | G8: =IF(D8=0,"—",REPT("▓",MIN(20,INT(C8/D8*20)))&REPT("░",MAX(0,20-MIN(20,INT(C8/D8*20))))) | H8: =IF(C8=0,"⬜",IF(C8/D8<0.8,"🟢",IF(C8/D8<=1,"🟡","🔴")))
B9: 📱 Abonnements | C9: =S18!J9+S19!J9+S20!J9+S21!J9 | D9: =S18!K9+S19!K9+S20!K9+S21!K9 | E9: =D9-C9 | F9: =IF(D9=0,0,C9/D9) | G9: =IF(D9=0,"—",REPT("▓",MIN(20,INT(C9/D9*20)))&REPT("░",MAX(0,20-MIN(20,INT(C9/D9*20))))) | H9: =IF(C9=0,"⬜",IF(C9/D9<0.8,"🟢",IF(C9/D9<=1,"🟡","🔴")))
B10: 👗 Shopping | C10: =S18!J10+S19!J10+S20!J10+S21!J10 | D10: =S18!K10+S19!K10+S20!K10+S21!K10 | E10: =D10-C10 | F10: =IF(D10=0,0,C10/D10) | G10: =IF(D10=0,"—",REPT("▓",MIN(20,INT(C10/D10*20)))&REPT("░",MAX(0,20-MIN(20,INT(C10/D10*20))))) | H10: =IF(C10=0,"⬜",IF(C10/D10<0.8,"🟢",IF(C10/D10<=1,"🟡","🔴")))
B11: 💡 Divers | C11: =S18!J11+S19!J11+S20!J11+S21!J11 | D11: =S18!K11+S19!K11+S20!K11+S21!K11 | E11: =D11-C11 | F11: =IF(D11=0,0,C11/D11) | G11: =IF(D11=0,"—",REPT("▓",MIN(20,INT(C11/D11*20)))&REPT("░",MAX(0,20-MIN(20,INT(C11/D11*20))))) | H11: =IF(C11=0,"⬜",IF(C11/D11<0.8,"🟢",IF(C11/D11<=1,"🟡","🔴")))
B12: TOTAL MENSUEL | C12: =SUM(C4:C11) | D12: =SUM(D4:D11) | E12: =SUM(E4:E11) | F12: =IF(D12=0,0,C12/D12) | G12: =IF(D12=0,"—",REPT("▓",MIN(20,INT(C12/D12*20)))&REPT("░",MAX(0,20-MIN(20,INT(C12/D12*20))))) | H12: =IF(C12=0,"⬜",IF(C12/D12<0.8,"🟢",IF(C12/D12<=1,"🟡","🔴")))

Sheet Juin
B2: 📅 JUIN — Récapitulatif mensuel (semaines 22–26)
B3: Catégorie | C3: Total dépensé | D3: Budget mensuel | E3: Restant | F3: % utilisé | G3: ▓▓▓ Progression | H3: 🚦
B4: 🏠 Logement | C4: =S22!J4+S23!J4+S24!J4+S25!J4+S26!J4 | D4: =S22!K4+S23!K4+S24!K4+S25!K4+S26!K4 | E4: =D4-C4 | F4: =IF(D4=0,0,C4/D4) | G4: =IF(D4=0,"—",REPT("▓",MIN(20,INT(C4/D4*20)))&REPT("░",MAX(0,20-MIN(20,INT(C4/D4*20))))) | H4: =IF(C4=0,"⬜",IF(C4/D4<0.8,"🟢",IF(C4/D4<=1,"🟡","🔴")))
B5: 🛒 Alimentation | C5: =S22!J5+S23!J5+S24!J5+S25!J5+S26!J5 | D5: =S22!K5+S23!K5+S24!K5+S25!K5+S26!K5 | E5: =D5-C5 | F5: =IF(D5=0,0,C5/D5) | G5: =IF(D5=0,"—",REPT("▓",MIN(20,INT(C5/D5*20)))&REPT("░",MAX(0,20-MIN(20,INT(C5/D5*20))))) | H5: =IF(C5=0,"⬜",IF(C5/D5<0.8,"🟢",IF(C5/D5<=1,"🟡","🔴")))
B6: 🚗 Transport | C6: =S22!J6+S23!J6+S24!J6+S25!J6+S26!J6 | D6: =S22!K6+S23!K6+S24!K6+S25!K6+S26!K6 | E6: =D6-C6 | F6: =IF(D6=0,0,C6/D6) | G6: =IF(D6=0,"—",REPT("▓",MIN(20,INT(C6/D6*20)))&REPT("░",MAX(0,20-MIN(20,INT(C6/D6*20))))) | H6: =IF(C6=0,"⬜",IF(C6/D6<0.8,"🟢",IF(C6/D6<=1,"🟡","🔴")))
B7: 💊 Santé | C7: =S22!J7+S23!J7+S24!J7+S25!J7+S26!J7 | D7: =S22!K7+S23!K7+S24!K7+S25!K7+S26!K7 | E7: =D7-C7 | F7: =IF(D7=0,0,C7/D7) | G7: =IF(D7=0,"—",REPT("▓",MIN(20,INT(C7/D7*20)))&REPT("░",MAX(0,20-MIN(20,INT(C7/D7*20))))) | H7: =IF(C7=0,"⬜",IF(C7/D7<0.8,"🟢",IF(C7/D7<=1,"🟡","🔴")))
B8: 🎮 Loisirs | C8: =S22!J8+S23!J8+S24!J8+S25!J8+S26!J8 | D8: =S22!K8+S23!K8+S24!K8+S25!K8+S26!K8 | E8: =D8-C8 | F8: =IF(D8=0,0,C8/D8) | G8: =IF(D8=0,"—",REPT("▓",MIN(20,INT(C8/D8*20)))&REPT("░",MAX(0,20-MIN(20,INT(C8/D8*20))))) | H8: =IF(C8=0,"⬜",IF(C8/D8<0.8,"🟢",IF(C8/D8<=1,"🟡","🔴")))
B9: 📱 Abonnements | C9: =S22!J9+S23!J9+S24!J9+S25!J9+S26!J9 | D9: =S22!K9+S23!K9+S24!K9+S25!K9+S26!K9 | E9: =D9-C9 | F9: =IF(D9=0,0,C9/D9) | G9: =IF(D9=0,"—",REPT("▓",MIN(20,INT(C9/D9*20)))&REPT("░",MAX(0,20-MIN(20,INT(C9/D9*20))))) | H9: =IF(C9=0,"⬜",IF(C9/D9<0.8,"🟢",IF(C9/D9<=1,"🟡","🔴")))
B10: 👗 Shopping | C10: =S22!J10+S23!J10+S24!J10+S25!J10+S26!J10 | D10: =S22!K10+S23!K10+S24!K10+S25!K10+S26!K10 | E10: =D10-C10 | F10: =IF(D10=0,0,C10/D10) | G10: =IF(D10=0,"—",REPT("▓",MIN(20,INT(C10/D10*20)))&REPT("░",MAX(0,20-MIN(20,INT(C10/D10*20))))) | H10: =IF(C10=0,"⬜",IF(C10/D10<0.8,"🟢",IF(C10/D10<=1,"🟡","🔴")))
B11: 💡 Divers | C11: =S22!J11+S23!J11+S24!J11+S25!J11+S26!J11 | D11: =S22!K11+S23!K11+S24!K11+S25!K11+S26!K11 | E11: =D11-C11 | F11: =IF(D11=0,0,C11/D11) | G11: =IF(D11=0,"—",REPT("▓",MIN(20,INT(C11/D11*20)))&REPT("░",MAX(0,20-MIN(20,INT(C11/D11*20))))) | H11: =IF(C11=0,"⬜",IF(C11/D11<0.8,"🟢",IF(C11/D11<=1,"🟡","🔴")))
B12: TOTAL MENSUEL | C12: =SUM(C4:C11) | D12: =SUM(D4:D11) | E12: =SUM(E4:E11) | F12: =IF(D12=0,0,C12/D12) | G12: =IF(D12=0,"—",REPT("▓",MIN(20,INT(C12/D12*20)))&REPT("░",MAX(0,20-MIN(20,INT(C12/D12*20))))) | H12: =IF(C12=0,"⬜",IF(C12/D12<0.8,"🟢",IF(C12/D12<=1,"🟡","🔴")))

Sheet Juillet
B2: 📅 JUILLET — Récapitulatif mensuel (semaines 27–30)
B3: Catégorie | C3: Total dépensé | D3: Budget mensuel | E3: Restant | F3: % utilisé | G3: ▓▓▓ Progression | H3: 🚦
B4: 🏠 Logement | C4: =S27!J4+S28!J4+S29!J4+S30!J4 | D4: =S27!K4+S28!K4+S29!K4+S30!K4 | E4: =D4-C4 | F4: =IF(D4=0,0,C4/D4) | G4: =IF(D4=0,"—",REPT("▓",MIN(20,INT(C4/D4*20)))&REPT("░",MAX(0,20-MIN(20,INT(C4/D4*20))))) | H4: =IF(C4=0,"⬜",IF(C4/D4<0.8,"🟢",IF(C4/D4<=1,"🟡","🔴")))
B5: 🛒 Alimentation | C5: =S27!J5+S28!J5+S29!J5+S30!J5 | D5: =S27!K5+S28!K5+S29!K5+S30!K5 | E5: =D5-C5 | F5: =IF(D5=0,0,C5/D5) | G5: =IF(D5=0,"—",REPT("▓",MIN(20,INT(C5/D5*20)))&REPT("░",MAX(0,20-MIN(20,INT(C5/D5*20))))) | H5: =IF(C5=0,"⬜",IF(C5/D5<0.8,"🟢",IF(C5/D5<=1,"🟡","🔴")))
B6: 🚗 Transport | C6: =S27!J6+S28!J6+S29!J6+S30!J6 | D6: =S27!K6+S28!K6+S29!K6+S30!K6 | E6: =D6-C6 | F6: =IF(D6=0,0,C6/D6) | G6: =IF(D6=0,"—",REPT("▓",MIN(20,INT(C6/D6*20)))&REPT("░",MAX(0,20-MIN(20,INT(C6/D6*20))))) | H6: =IF(C6=0,"⬜",IF(C6/D6<0.8,"🟢",IF(C6/D6<=1,"🟡","🔴")))
B7: 💊 Santé | C7: =S27!J7+S28!J7+S29!J7+S30!J7 | D7: =S27!K7+S28!K7+S29!K7+S30!K7 | E7: =D7-C7 | F7: =IF(D7=0,0,C7/D7) | G7: =IF(D7=0,"—",REPT("▓",MIN(20,INT(C7/D7*20)))&REPT("░",MAX(0,20-MIN(20,INT(C7/D7*20))))) | H7: =IF(C7=0,"⬜",IF(C7/D7<0.8,"🟢",IF(C7/D7<=1,"🟡","🔴")))
B8: 🎮 Loisirs | C8: =S27!J8+S28!J8+S29!J8+S30!J8 | D8: =S27!K8+S28!K8+S29!K8+S30!K8 | E8: =D8-C8 | F8: =IF(D8=0,0,C8/D8) | G8: =IF(D8=0,"—",REPT("▓",MIN(20,INT(C8/D8*20)))&REPT("░",MAX(0,20-MIN(20,INT(C8/D8*20))))) | H8: =IF(C8=0,"⬜",IF(C8/D8<0.8,"🟢",IF(C8/D8<=1,"🟡","🔴")))
B9: 📱 Abonnements | C9: =S27!J9+S28!J9+S29!J9+S30!J9 | D9: =S27!K9+S28!K9+S29!K9+S30!K9 | E9: =D9-C9 | F9: =IF(D9=0,0,C9/D9) | G9: =IF(D9=0,"—",REPT("▓",MIN(20,INT(C9/D9*20)))&REPT("░",MAX(0,20-MIN(20,INT(C9/D9*20))))) | H9: =IF(C9=0,"⬜",IF(C9/D9<0.8,"🟢",IF(C9/D9<=1,"🟡","🔴")))
B10: 👗 Shopping | C10: =S27!J10+S28!J10+S29!J10+S30!J10 | D10: =S27!K10+S28!K10+S29!K10+S30!K10 | E10: =D10-C10 | F10: =IF(D10=0,0,C10/D10) | G10: =IF(D10=0,"—",REPT("▓",MIN(20,INT(C10/D10*20)))&REPT("░",MAX(0,20-MIN(20,INT(C10/D10*20))))) | H10: =IF(C10=0,"⬜",IF(C10/D10<0.8,"🟢",IF(C10/D10<=1,"🟡","🔴")))
B11: 💡 Divers | C11: =S27!J11+S28!J11+S29!J11+S30!J11 | D11: =S27!K11+S28!K11+S29!K11+S30!K11 | E11: =D11-C11 | F11: =IF(D11=0,0,C11/D11) | G11: =IF(D11=0,"—",REPT("▓",MIN(20,INT(C11/D11*20)))&REPT("░",MAX(0,20-MIN(20,INT(C11/D11*20))))) | H11: =IF(C11=0,"⬜",IF(C11/D11<0.8,"🟢",IF(C11/D11<=1,"🟡","🔴")))
B12: TOTAL MENSUEL | C12: =SUM(C4:C11) | D12: =SUM(D4:D11) | E12: =SUM(E4:E11) | F12: =IF(D12=0,0,C12/D12) | G12: =IF(D12=0,"—",REPT("▓",MIN(20,INT(C12/D12*20)))&REPT("░",MAX(0,20-MIN(20,INT(C12/D12*20))))) | H12: =IF(C12=0,"⬜",IF(C12/D12<0.8,"🟢",IF(C12/D12<=1,"🟡","🔴")))

Sheet Aout
B2: 📅 AOÛT — Récapitulatif mensuel (semaines 31–34)
B3: Catégorie | C3: Total dépensé | D3: Budget mensuel | E3: Restant | F3: % utilisé | G3: ▓▓▓ Progression | H3: 🚦
B4: 🏠 Logement | C4: =S31!J4+S32!J4+S33!J4+S34!J4 | D4: =S31!K4+S32!K4+S33!K4+S34!K4 | E4: =D4-C4 | F4: =IF(D4=0,0,C4/D4) | G4: =IF(D4=0,"—",REPT("▓",MIN(20,INT(C4/D4*20)))&REPT("░",MAX(0,20-MIN(20,INT(C4/D4*20))))) | H4: =IF(C4=0,"⬜",IF(C4/D4<0.8,"🟢",IF(C4/D4<=1,"🟡","🔴")))
B5: 🛒 Alimentation | C5: =S31!J5+S32!J5+S33!J5+S34!J5 | D5: =S31!K5+S32!K5+S33!K5+S34!K5 | E5: =D5-C5 | F5: =IF(D5=0,0,C5/D5) | G5: =IF(D5=0,"—",REPT("▓",MIN(20,INT(C5/D5*20)))&REPT("░",MAX(0,20-MIN(20,INT(C5/D5*20))))) | H5: =IF(C5=0,"⬜",IF(C5/D5<0.8,"🟢",IF(C5/D5<=1,"🟡","🔴")))
B6: 🚗 Transport | C6: =S31!J6+S32!J6+S33!J6+S34!J6 | D6: =S31!K6+S32!K6+S33!K6+S34!K6 | E6: =D6-C6 | F6: =IF(D6=0,0,C6/D6) | G6: =IF(D6=0,"—",REPT("▓",MIN(20,INT(C6/D6*20)))&REPT("░",MAX(0,20-MIN(20,INT(C6/D6*20))))) | H6: =IF(C6=0,"⬜",IF(C6/D6<0.8,"🟢",IF(C6/D6<=1,"🟡","🔴")))
B7: 💊 Santé | C7: =S31!J7+S32!J7+S33!J7+S34!J7 | D7: =S31!K7+S32!K7+S33!K7+S34!K7 | E7: =D7-C7 | F7: =IF(D7=0,0,C7/D7) | G7: =IF(D7=0,"—",REPT("▓",MIN(20,INT(C7/D7*20)))&REPT("░",MAX(0,20-MIN(20,INT(C7/D7*20))))) | H7: =IF(C7=0,"⬜",IF(C7/D7<0.8,"🟢",IF(C7/D7<=1,"🟡","🔴")))
B8: 🎮 Loisirs | C8: =S31!J8+S32!J8+S33!J8+S34!J8 | D8: =S31!K8+S32!K8+S33!K8+S34!K8 | E8: =D8-C8 | F8: =IF(D8=0,0,C8/D8) | G8: =IF(D8=0,"—",REPT("▓",MIN(20,INT(C8/D8*20)))&REPT("░",MAX(0,20-MIN(20,INT(C8/D8*20))))) | H8: =IF(C8=0,"⬜",IF(C8/D8<0.8,"🟢",IF(C8/D8<=1,"🟡","🔴")))
B9: 📱 Abonnements | C9: =S31!J9+S32!J9+S33!J9+S34!J9 | D9: =S31!K9+S32!K9+S33!K9+S34!K9 | E9: =D9-C9 | F9: =IF(D9=0,0,C9/D9) | G9: =IF(D9=0,"—",REPT("▓",MIN(20,INT(C9/D9*20)))&REPT("░",MAX(0,20-MIN(20,INT(C9/D9*20))))) | H9: =IF(C9=0,"⬜",IF(C9/D9<0.8,"🟢",IF(C9/D9<=1,"🟡","🔴")))
B10: 👗 Shopping | C10: =S31!J10+S32!J10+S33!J10+S34!J10 | D10: =S31!K10+S32!K10+S33!K10+S34!K10 | E10: =D10-C10 | F10: =IF(D10=0,0,C10/D10) | G10: =IF(D10=0,"—",REPT("▓",MIN(20,INT(C10/D10*20)))&REPT("░",MAX(0,20-MIN(20,INT(C10/D10*20))))) | H10: =IF(C10=0,"⬜",IF(C10/D10<0.8,"🟢",IF(C10/D10<=1,"🟡","🔴")))
B11: 💡 Divers | C11: =S31!J11+S32!J11+S33!J11+S34!J11 | D11: =S31!K11+S32!K11+S33!K11+S34!K11 | E11: =D11-C11 | F11: =IF(D11=0,0,C11/D11) | G11: =IF(D11=0,"—",REPT("▓",MIN(20,INT(C11/D11*20)))&REPT("░",MAX(0,20-MIN(20,INT(C11/D11*20))))) | H11: =IF(C11=0,"⬜",IF(C11/D11<0.8,"🟢",IF(C11/D11<=1,"🟡","🔴")))
B12: TOTAL MENSUEL | C12: =SUM(C4:C11) | D12: =SUM(D4:D11) | E12: =SUM(E4:E11) | F12: =IF(D12=0,0,C12/D12) | G12: =IF(D12=0,"—",REPT("▓",MIN(20,INT(C12/D12*20)))&REPT("░",MAX(0,20-MIN(20,INT(C12/D12*20))))) | H12: =IF(C12=0,"⬜",IF(C12/D12<0.8,"🟢",IF(C12/D12<=1,"🟡","🔴")))

Sheet Septembre
B2: 📅 SEPTEMBRE — Récapitulatif mensuel (semaines 35–39)
B3: Catégorie | C3: Total dépensé | D3: Budget mensuel | E3: Restant | F3: % utilisé | G3: ▓▓▓ Progression | H3: 🚦
B4: 🏠 Logement | C4: =S35!J4+S36!J4+S37!J4+S38!J4+S39!J4 | D4: =S35!K4+S36!K4+S37!K4+S38!K4+S39!K4 | E4: =D4-C4 | F4: =IF(D4=0,0,C4/D4) | G4: =IF(D4=0,"—",REPT("▓",MIN(20,INT(C4/D4*20)))&REPT("░",MAX(0,20-MIN(20,INT(C4/D4*20))))) | H4: =IF(C4=0,"⬜",IF(C4/D4<0.8,"🟢",IF(C4/D4<=1,"🟡","🔴")))
B5: 🛒 Alimentation | C5: =S35!J5+S36!J5+S37!J5+S38!J5+S39!J5 | D5: =S35!K5+S36!K5+S37!K5+S38!K5+S39!K5 | E5: =D5-C5 | F5: =IF(D5=0,0,C5/D5) | G5: =IF(D5=0,"—",REPT("▓",MIN(20,INT(C5/D5*20)))&REPT("░",MAX(0,20-MIN(20,INT(C5/D5*20))))) | H5: =IF(C5=0,"⬜",IF(C5/D5<0.8,"🟢",IF(C5/D5<=1,"🟡","🔴")))
B6: 🚗 Transport | C6: =S35!J6+S36!J6+S37!J6+S38!J6+S39!J6 | D6: =S35!K6+S36!K6+S37!K6+S38!K6+S39!K6 | E6: =D6-C6 | F6: =IF(D6=0,0,C6/D6) | G6: =IF(D6=0,"—",REPT("▓",MIN(20,INT(C6/D6*20)))&REPT("░",MAX(0,20-MIN(20,INT(C6/D6*20))))) | H6: =IF(C6=0,"⬜",IF(C6/D6<0.8,"🟢",IF(C6/D6<=1,"🟡","🔴")))
B7: 💊 Santé | C7: =S35!J7+S36!J7+S37!J7+S38!J7+S39!J7 | D7: =S35!K7+S36!K7+S37!K7+S38!K7+S39!K7 | E7: =D7-C7 | F7: =IF(D7=0,0,C7/D7) | G7: =IF(D7=0,"—",REPT("▓",MIN(20,INT(C7/D7*20)))&REPT("░",MAX(0,20-MIN(20,INT(C7/D7*20))))) | H7: =IF(C7=0,"⬜",IF(C7/D7<0.8,"🟢",IF(C7/D7<=1,"🟡","🔴")))
B8: 🎮 Loisirs | C8: =S35!J8+S36!J8+S37!J8+S38!J8+S39!J8 | D8: =S35!K8+S36!K8+S37!K8+S38!K8+S39!K8 | E8: =D8-C8 | F8: =IF(D8=0,0,C8/D8) | G8: =IF(D8=0,"—",REPT("▓",MIN(20,INT(C8/D8*20)))&REPT("░",MAX(0,20-MIN(20,INT(C8/D8*20))))) | H8: =IF(C8=0,"⬜",IF(C8/D8<0.8,"🟢",IF(C8/D8<=1,"🟡","🔴")))
B9: 📱 Abonnements | C9: =S35!J9+S36!J9+S37!J9+S38!J9+S39!J9 | D9: =S35!K9+S36!K9+S37!K9+S38!K9+S39!K9 | E9: =D9-C9 | F9: =IF(D9=0,0,C9/D9) | G9: =IF(D9=0,"—",REPT("▓",MIN(20,INT(C9/D9*20)))&REPT("░",MAX(0,20-MIN(20,INT(C9/D9*20))))) | H9: =IF(C9=0,"⬜",IF(C9/D9<0.8,"🟢",IF(C9/D9<=1,"🟡","🔴")))
B10: 👗 Shopping | C10: =S35!J10+S36!J10+S37!J10+S38!J10+S39!J10 | D10: =S35!K10+S36!K10+S37!K10+S38!K10+S39!K10 | E10: =D10-C10 | F10: =IF(D10=0,0,C10/D10) | G10: =IF(D10=0,"—",REPT("▓",MIN(20,INT(C10/D10*20)))&REPT("░",MAX(0,20-MIN(20,INT(C10/D10*20))))) | H10: =IF(C10=0,"⬜",IF(C10/D10<0.8,"🟢",IF(C10/D10<=1,"🟡","🔴")))
B11: 💡 Divers | C11: =S35!J11+S36!J11+S37!J11+S38!J11+S39!J11 | D11: =S35!K11+S36!K11+S37!K11+S38!K11+S39!K11 | E11: =D11-C11 | F11: =IF(D11=0,0,C11/D11) | G11: =IF(D11=0,"—",REPT("▓",MIN(20,INT(C11/D11*20)))&REPT("░",MAX(0,20-MIN(20,INT(C11/D11*20))))) | H11: =IF(C11=0,"⬜",IF(C11/D11<0.8,"🟢",IF(C11/D11<=1,"🟡","🔴")))
B12: TOTAL MENSUEL | C12: =SUM(C4:C11) | D12: =SUM(D4:D11) | E12: =SUM(E4:E11) | F12: =IF(D12=0,0,C12/D12) | G12: =IF(D12=0,"—",REPT("▓",MIN(20,INT(C12/D12*20)))&REPT("░",MAX(0,20-MIN(20,INT(C12/D12*20))))) | H12: =IF(C12=0,"⬜",IF(C12/D12<0.8,"🟢",IF(C12/D12<=1,"🟡","🔴")))

Sheet Octobre
B2: 📅 OCTOBRE — Récapitulatif mensuel (semaines 40–43)
B3: Catégorie | C3: Total dépensé | D3: Budget mensuel | E3: Restant | F3: % utilisé | G3: ▓▓▓ Progression | H3: 🚦
B4: 🏠 Logement | C4: =S40!J4+S41!J4+S42!J4+S43!J4 | D4: =S40!K4+S41!K4+S42!K4+S43!K4 | E4: =D4-C4 | F4: =IF(D4=0,0,C4/D4) | G4: =IF(D4=0,"—",REPT("▓",MIN(20,INT(C4/D4*20)))&REPT("░",MAX(0,20-MIN(20,INT(C4/D4*20))))) | H4: =IF(C4=0,"⬜",IF(C4/D4<0.8,"🟢",IF(C4/D4<=1,"🟡","🔴")))
B5: 🛒 Alimentation | C5: =S40!J5+S41!J5+S42!J5+S43!J5 | D5: =S40!K5+S41!K5+S42!K5+S43!K5 | E5: =D5-C5 | F5: =IF(D5=0,0,C5/D5) | G5: =IF(D5=0,"—",REPT("▓",MIN(20,INT(C5/D5*20)))&REPT("░",MAX(0,20-MIN(20,INT(C5/D5*20))))) | H5: =IF(C5=0,"⬜",IF(C5/D5<0.8,"🟢",IF(C5/D5<=1,"🟡","🔴")))
B6: 🚗 Transport | C6: =S40!J6+S41!J6+S42!J6+S43!J6 | D6: =S40!K6+S41!K6+S42!K6+S43!K6 | E6: =D6-C6 | F6: =IF(D6=0,0,C6/D6) | G6: =IF(D6=0,"—",REPT("▓",MIN(20,INT(C6/D6*20)))&REPT("░",MAX(0,20-MIN(20,INT(C6/D6*20))))) | H6: =IF(C6=0,"⬜",IF(C6/D6<0.8,"🟢",IF(C6/D6<=1,"🟡","🔴")))
B7: 💊 Santé | C7: =S40!J7+S41!J7+S42!J7+S43!J7 | D7: =S40!K7+S41!K7+S42!K7+S43!K7 | E7: =D7-C7 | F7: =IF(D7=0,0,C7/D7) | G7: =IF(D7=0,"—",REPT("▓",MIN(20,INT(C7/D7*20)))&REPT("░",MAX(0,20-MIN(20,INT(C7/D7*20))))) | H7: =IF(C7=0,"⬜",IF(C7/D7<0.8,"🟢",IF(C7/D7<=1,"🟡","🔴")))
B8: 🎮 Loisirs | C8: =S40!J8+S41!J8+S42!J8+S43!J8 | D8: =S40!K8+S41!K8+S42!K8+S43!K8 | E8: =D8-C8 | F8: =IF(D8=0,0,C8/D8) | G8: =IF(D8=0,"—",REPT("▓",MIN(20,INT(C8/D8*20)))&REPT("░",MAX(0,20-MIN(20,INT(C8/D8*20))))) | H8: =IF(C8=0,"⬜",IF(C8/D8<0.8,"🟢",IF(C8/D8<=1,"🟡","🔴")))
B9: 📱 Abonnements | C9: =S40!J9+S41!J9+S42!J9+S43!J9 | D9: =S40!K9+S41!K9+S42!K9+S43!K9 | E9: =D9-C9 | F9: =IF(D9=0,0,C9/D9) | G9: =IF(D9=0,"—",REPT("▓",MIN(20,INT(C9/D9*20)))&REPT("░",MAX(0,20-MIN(20,INT(C9/D9*20))))) | H9: =IF(C9=0,"⬜",IF(C9/D9<0.8,"🟢",IF(C9/D9<=1,"🟡","🔴")))
B10: 👗 Shopping | C10: =S40!J10+S41!J10+S42!J10+S43!J10 | D10: =S40!K10+S41!K10+S42!K10+S43!K10 | E10: =D10-C10 | F10: =IF(D10=0,0,C10/D10) | G10: =IF(D10=0,"—",REPT("▓",MIN(20,INT(C10/D10*20)))&REPT("░",MAX(0,20-MIN(20,INT(C10/D10*20))))) | H10: =IF(C10=0,"⬜",IF(C10/D10<0.8,"🟢",IF(C10/D10<=1,"🟡","🔴")))
B11: 💡 Divers | C11: =S40!J11+S41!J11+S42!J11+S43!J11 | D11: =S40!K11+S41!K11+S42!K11+S43!K11 | E11: =D11-C11 | F11: =IF(D11=0,0,C11/D11) | G11: =IF(D11=0,"—",REPT("▓",MIN(20,INT(C11/D11*20)))&REPT("░",MAX(0,20-MIN(20,INT(C11/D11*20))))) | H11: =IF(C11=0,"⬜",IF(C11/D11<0.8,"🟢",IF(C11/D11<=1,"🟡","🔴")))
B12: TOTAL MENSUEL | C12: =SUM(C4:C11) | D12: =SUM(D4:D11) | E12: =SUM(E4:E11) | F12: =IF(D12=0,0,C12/D12) | G12: =IF(D12=0,"—",REPT("▓",MIN(20,INT(C12/D12*20)))&REPT("░",MAX(0,20-MIN(20,INT(C12/D12*20))))) | H12: =IF(C12=0,"⬜",IF(C12/D12<0.8,"🟢",IF(C12/D12<=1,"🟡","🔴")))

Sheet Novembre
B2: 📅 NOVEMBRE — Récapitulatif mensuel (semaines 44–47)
B3: Catégorie | C3: Total dépensé | D3: Budget mensuel | E3: Restant | F3: % utilisé | G3: ▓▓▓ Progression | H3: 🚦
B4: 🏠 Logement | C4: =S44!J4+S45!J4+S46!J4+S47!J4 | D4: =S44!K4+S45!K4+S46!K4+S47!K4 | E4: =D4-C4 | F4: =IF(D4=0,0,C4/D4) | G4: =IF(D4=0,"—",REPT("▓",MIN(20,INT(C4/D4*20)))&REPT("░",MAX(0,20-MIN(20,INT(C4/D4*20))))) | H4: =IF(C4=0,"⬜",IF(C4/D4<0.8,"🟢",IF(C4/D4<=1,"🟡","🔴")))
B5: 🛒 Alimentation | C5: =S44!J5+S45!J5+S46!J5+S47!J5 | D5: =S44!K5+S45!K5+S46!K5+S47!K5 | E5: =D5-C5 | F5: =IF(D5=0,0,C5/D5) | G5: =IF(D5=0,"—",REPT("▓",MIN(20,INT(C5/D5*20)))&REPT("░",MAX(0,20-MIN(20,INT(C5/D5*20))))) | H5: =IF(C5=0,"⬜",IF(C5/D5<0.8,"🟢",IF(C5/D5<=1,"🟡","🔴")))
B6: 🚗 Transport | C6: =S44!J6+S45!J6+S46!J6+S47!J6 | D6: =S44!K6+S45!K6+S46!K6+S47!K6 | E6: =D6-C6 | F6: =IF(D6=0,0,C6/D6) | G6: =IF(D6=0,"—",REPT("▓",MIN(20,INT(C6/D6*20)))&REPT("░",MAX(0,20-MIN(20,INT(C6/D6*20))))) | H6: =IF(C6=0,"⬜",IF(C6/D6<0.8,"🟢",IF(C6/D6<=1,"🟡","🔴")))
B7: 💊 Santé | C7: =S44!J7+S45!J7+S46!J7+S47!J7 | D7: =S44!K7+S45!K7+S46!K7+S47!K7 | E7: =D7-C7 | F7: =IF(D7=0,0,C7/D7) | G7: =IF(D7=0,"—",REPT("▓",MIN(20,INT(C7/D7*20)))&REPT("░",MAX(0,20-MIN(20,INT(C7/D7*20))))) | H7: =IF(C7=0,"⬜",IF(C7/D7<0.8,"🟢",IF(C7/D7<=1,"🟡","🔴")))
B8: 🎮 Loisirs | C8: =S44!J8+S45!J8+S46!J8+S47!J8 | D8: =S44!K8+S45!K8+S46!K8+S47!K8 | E8: =D8-C8 | F8: =IF(D8=0,0,C8/D8) | G8: =IF(D8=0,"—",REPT("▓",MIN(20,INT(C8/D8*20)))&REPT("░",MAX(0,20-MIN(20,INT(C8/D8*20))))) | H8: =IF(C8=0,"⬜",IF(C8/D8<0.8,"🟢",IF(C8/D8<=1,"🟡","🔴")))
B9: 📱 Abonnements | C9: =S44!J9+S45!J9+S46!J9+S47!J9 | D9: =S44!K9+S45!K9+S46!K9+S47!K9 | E9: =D9-C9 | F9: =IF(D9=0,0,C9/D9) | G9: =IF(D9=0,"—",REPT("▓",MIN(20,INT(C9/D9*20)))&REPT("░",MAX(0,20-MIN(20,INT(C9/D9*20))))) | H9: =IF(C9=0,"⬜",IF(C9/D9<0.8,"🟢",IF(C9/D9<=1,"🟡","🔴")))
B10: 👗 Shopping | C10: =S44!J10+S45!J10+S46!J10+S47!J10 | D10: =S44!K10+S45!K10+S46!K10+S47!K10 | E10: =D10-C10 | F10: =IF(D10=0,0,C10/D10) | G10: =IF(D10=0,"—",REPT("▓",MIN(20,INT(C10/D10*20)))&REPT("░",MAX(0,20-MIN(20,INT(C10/D10*20))))) | H10: =IF(C10=0,"⬜",IF(C10/D10<0.8,"🟢",IF(C10/D10<=1,"🟡","🔴")))
B11: 💡 Divers | C11: =S44!J11+S45!J11+S46!J11+S47!J11 | D11: =S44!K11+S45!K11+S46!K11+S47!K11 | E11: =D11-C11 | F11: =IF(D11=0,0,C11/D11) | G11: =IF(D11=0,"—",REPT("▓",MIN(20,INT(C11/D11*20)))&REPT("░",MAX(0,20-MIN(20,INT(C11/D11*20))))) | H11: =IF(C11=0,"⬜",IF(C11/D11<0.8,"🟢",IF(C11/D11<=1,"🟡","🔴")))
B12: TOTAL MENSUEL | C12: =SUM(C4:C11) | D12: =SUM(D4:D11) | E12: =SUM(E4:E11) | F12: =IF(D12=0,0,C12/D12) | G12: =IF(D12=0,"—",REPT("▓",MIN(20,INT(C12/D12*20)))&REPT("░",MAX(0,20-MIN(20,INT(C12/D12*20))))) | H12: =IF(C12=0,"⬜",IF(C12/D12<0.8,"🟢",IF(C12/D12<=1,"🟡","🔴")))

Sheet Decembre
B2: 📅 DÉCEMBRE — Récapitulatif mensuel (semaines 48–52)
B3: Catégorie | C3: Total dépensé | D3: Budget mensuel | E3: Restant | F3: % utilisé | G3: ▓▓▓ Progression | H3: 🚦
B4: 🏠 Logement | C4: =S48!J4+S49!J4+S50!J4+S51!J4+S52!J4 | D4: =S48!K4+S49!K4+S50!K4+S51!K4+S52!K4 | E4: =D4-C4 | F4: =IF(D4=0,0,C4/D4) | G4: =IF(D4=0,"—",REPT("▓",MIN(20,INT(C4/D4*20)))&REPT("░",MAX(0,20-MIN(20,INT(C4/D4*20))))) | H4: =IF(C4=0,"⬜",IF(C4/D4<0.8,"🟢",IF(C4/D4<=1,"🟡","🔴")))
B5: 🛒 Alimentation | C5: =S48!J5+S49!J5+S50!J5+S51!J5+S52!J5 | D5: =S48!K5+S49!K5+S50!K5+S51!K5+S52!K5 | E5: =D5-C5 | F5: =IF(D5=0,0,C5/D5) | G5: =IF(D5=0,"—",REPT("▓",MIN(20,INT(C5/D5*20)))&REPT("░",MAX(0,20-MIN(20,INT(C5/D5*20))))) | H5: =IF(C5=0,"⬜",IF(C5/D5<0.8,"🟢",IF(C5/D5<=1,"🟡","🔴")))
B6: 🚗 Transport | C6: =S48!J6+S49!J6+S50!J6+S51!J6+S52!J6 | D6: =S48!K6+S49!K6+S50!K6+S51!K6+S52!K6 | E6: =D6-C6 | F6: =IF(D6=0,0,C6/D6) | G6: =IF(D6=0,"—",REPT("▓",MIN(20,INT(C6/D6*20)))&REPT("░",MAX(0,20-MIN(20,INT(C6/D6*20))))) | H6: =IF(C6=0,"⬜",IF(C6/D6<0.8,"🟢",IF(C6/D6<=1,"🟡","🔴")))
B7: 💊 Santé | C7: =S48!J7+S49!J7+S50!J7+S51!J7+S52!J7 | D7: =S48!K7+S49!K7+S50!K7+S51!K7+S52!K7 | E7: =D7-C7 | F7: =IF(D7=0,0,C7/D7) | G7: =IF(D7=0,"—",REPT("▓",MIN(20,INT(C7/D7*20)))&REPT("░",MAX(0,20-MIN(20,INT(C7/D7*20))))) | H7: =IF(C7=0,"⬜",IF(C7/D7<0.8,"🟢",IF(C7/D7<=1,"🟡","🔴")))
B8: 🎮 Loisirs | C8: =S48!J8+S49!J8+S50!J8+S51!J8+S52!J8 | D8: =S48!K8+S49!K8+S50!K8+S51!K8+S52!K8 | E8: =D8-C8 | F8: =IF(D8=0,0,C8/D8) | G8: =IF(D8=0,"—",REPT("▓",MIN(20,INT(C8/D8*20)))&REPT("░",MAX(0,20-MIN(20,INT(C8/D8*20))))) | H8: =IF(C8=0,"⬜",IF(C8/D8<0.8,"🟢",IF(C8/D8<=1,"🟡","🔴")))
B9: 📱 Abonnements | C9: =S48!J9+S49!J9+S50!J9+S51!J9+S52!J9 | D9: =S48!K9+S49!K9+S50!K9+S51!K9+S52!K9 | E9: =D9-C9 | F9: =IF(D9=0,0,C9/D9) | G9: =IF(D9=0,"—",REPT("▓",MIN(20,INT(C9/D9*20)))&REPT("░",MAX(0,20-MIN(20,INT(C9/D9*20))))) | H9: =IF(C9=0,"⬜",IF(C9/D9<0.8,"🟢",IF(C9/D9<=1,"🟡","🔴")))
B10: 👗 Shopping | C10: =S48!J10+S49!J10+S50!J10+S51!J10+S52!J10 | D10: =S48!K10+S49!K10+S50!K10+S51!K10+S52!K10 | E10: =D10-C10 | F10: =IF(D10=0,0,C10/D10) | G10: =IF(D10=0,"—",REPT("▓",MIN(20,INT(C10/D10*20)))&REPT("░",MAX(0,20-MIN(20,INT(C10/D10*20))))) | H10: =IF(C10=0,"⬜",IF(C10/D10<0.8,"🟢",IF(C10/D10<=1,"🟡","🔴")))
B11: 💡 Divers | C11: =S48!J11+S49!J11+S50!J11+S51!J11+S52!J11 | D11: =S48!K11+S49!K11+S50!K11+S51!K11+S52!K11 | E11: =D11-C11 | F11: =IF(D11=0,0,C11/D11) | G11: =IF(D11=0,"—",REPT("▓",MIN(20,INT(C11/D11*20)))&REPT("░",MAX(0,20-MIN(20,INT(C11/D11*20))))) | H11: =IF(C11=0,"⬜",IF(C11/D11<0.8,"🟢",IF(C11/D11<=1,"🟡","🔴")))
B12: TOTAL MENSUEL | C12: =SUM(C4:C11) | D12: =SUM(D4:D11) | E12: =SUM(E4:E11) | F12: =IF(D12=0,0,C12/D12) | G12: =IF(D12=0,"—",REPT("▓",MIN(20,INT(C12/D12*20)))&REPT("░",MAX(0,20-MIN(20,INT(C12/D12*20))))) | H12: =IF(C12=0,"⬜",IF(C12/D12<0.8,"🟢",IF(C12/D12<=1,"🟡","🔴")))

Sheet S01
B2: 📅 SEMAINE 01 — Suivi de dépenses hebdomadaire
B3: Catégorie | C3: Lun | D3: Mar | E3: Mer | F3: Jeu | G3: Ven | H3: Sam | I3: Dim | J3: Total sem. | K3: Budget sem. | L3: % utilisé | M3: ▓▓▓ Progression | N3: 🚦
B4: 🏠 Logement | C4: 0 | D4: 0 | E4: 0 | F4: 0 | G4: 0 | H4: 0 | I4: 0 | J4: =SUM(C4:I4) | K4: 207 | L4: =IF(K4=0,0,J4/K4) | M4: =IF(K4=0,"—",REPT("▓",MIN(20,INT(J4/K4*20)))&REPT("░",MAX(0,20-MIN(20,INT(J4/K4*20))))) | N4: =IF(J4=0,"⬜",IF(J4/K4<0.8,"🟢",IF(J4/K4<=1,"🟡","🔴")))
B5: 🛒 Alimentation | C5: 0 | D5: 0 | E5: 0 | F5: 0 | G5: 0 | H5: 0 | I5: 0 | J5: =SUM(C5:I5) | K5: 104 | L5: =IF(K5=0,0,J5/K5) | M5: =IF(K5=0,"—",REPT("▓",MIN(20,INT(J5/K5*20)))&REPT("░",MAX(0,20-MIN(20,INT(J5/K5*20))))) | N5: =IF(J5=0,"⬜",IF(J5/K5<0.8,"🟢",IF(J5/K5<=1,"🟡","🔴")))
B6: 🚗 Transport | C6: 0 | D6: 0 | E6: 0 | F6: 0 | G6: 0 | H6: 0 | I6: 0 | J6: =SUM(C6:I6) | K6: 46 | L6: =IF(K6=0,0,J6/K6) | M6: =IF(K6=0,"—",REPT("▓",MIN(20,INT(J6/K6*20)))&REPT("░",MAX(0,20-MIN(20,INT(J6/K6*20))))) | N6: =IF(J6=0,"⬜",IF(J6/K6<0.8,"🟢",IF(J6/K6<=1,"🟡","🔴")))
B7: 💊 Santé | C7: 0 | D7: 0 | E7: 0 | F7: 0 | G7: 0 | H7: 0 | I7: 0 | J7: =SUM(C7:I7) | K7: 23 | L7: =IF(K7=0,0,J7/K7) | M7: =IF(K7=0,"—",REPT("▓",MIN(20,INT(J7/K7*20)))&REPT("░",MAX(0,20-MIN(20,INT(J7/K7*20))))) | N7: =IF(J7=0,"⬜",IF(J7/K7<0.8,"🟢",IF(J7/K7<=1,"🟡","🔴")))
B8: 🎮 Loisirs | C8: 0 | D8: 0 | E8: 0 | F8: 0 | G8: 0 | H8: 0 | I8: 0 | J8: =SUM(C8:I8) | K8: 35 | L8: =IF(K8=0,0,J8/K8) | M8: =IF(K8=0,"—",REPT("▓",MIN(20,INT(J8/K8*20)))&REPT("░",MAX(0,20-MIN(20,INT(J8/K8*20))))) | N8: =IF(J8=0,"⬜",IF(J8/K8<0.8,"🟢",IF(J8/K8<=1,"🟡","🔴")))
B9: 📱 Abonnements | C9: 0 | D9: 0 | E9: 0 | F9: 0 | G9: 0 | H9: 0 | I9: 0 | J9: =SUM(C9:I9) | K9: 14 | L9: =IF(K9=0,0,J9/K9) | M9: =IF(K9=0,"—",REPT("▓",MIN(20,INT(J9/K9*20)))&REPT("░",MAX(0,20-MIN(20,INT(J9/K9*20))))) | N9: =IF(J9=0,"⬜",IF(J9/K9<0.8,"🟢",IF(J9/K9<=1,"🟡","🔴")))
B10: 👗 Shopping | C10: 0 | D10: 0 | E10: 0 | F10: 0 | G10: 0 | H10: 0 | I10: 0 | J10: =SUM(C10:I10) | K10: 28 | L10: =IF(K10=0,0,J10/K10) | M10: =IF(K10=0,"—",REPT("▓",MIN(20,INT(J10/K10*20)))&REPT("░",MAX(0,20-MIN(20,INT(J10/K10*20))))) | N10: =IF(J10=0,"⬜",IF(J10/K10<0.8,"🟢",IF(J10/K10<=1,"🟡","🔴")))
B11: 💡 Divers | C11: 0 | D11: 0 | E11: 0 | F11: 0 | G11: 0 | H11: 0 | I11: 0 | J11: =SUM(C11:I11) | K11: 18 | L11: =IF(K11=0,0,J11/K11) | M11: =IF(K11=0,"—",REPT("▓",MIN(20,INT(J11/K11*20)))&REPT("░",MAX(0,20-MIN(20,INT(J11/K11*20))))) | N11: =IF(J11=0,"⬜",IF(J11/K11<0.8,"🟢",IF(J11/K11<=1,"🟡","🔴")))
B12: TOTAL SEMAINE | C12: =SUM(C4:C11) | D12: =SUM(D4:D11) | E12: =SUM(E4:E11) | F12: =SUM(F4:F11) | G12: =SUM(G4:G11) | H12: =SUM(H4:H11) | I12: =SUM(I4:I11) | J12: =SUM(J4:J11) | K12: =SUM(K4:K11) | L12: =IF(K12=0,0,J12/K12) | M12: =IF(K12=0,"—",REPT("▓",MIN(20,INT(J12/K12*20)))&REPT("░",MAX(0,20-MIN(20,INT(J12/K12*20))))) | N12: =IF(J12=0,"⬜",IF(J12/K12<0.8,"🟢",IF(J12/K12<=1,"🟡","🔴")))

Sheet S02
B2: 📅 SEMAINE 02 — Suivi de dépenses hebdomadaire
B3: Catégorie | C3: Lun | D3: Mar | E3: Mer | F3: Jeu | G3: Ven | H3: Sam | I3: Dim | J3: Total sem. | K3: Budget sem. | L3: % utilisé | M3: ▓▓▓ Progression | N3: 🚦
B4: 🏠 Logement | C4: 0 | D4: 0 | E4: 0 | F4: 0 | G4: 0 | H4: 0 | I4: 0 | J4: =SUM(C4:I4) | K4: 207 | L4: =IF(K4=0,0,J4/K4) | M4: =IF(K4=0,"—",REPT("▓",MIN(20,INT(J4/K4*20)))&REPT("░",MAX(0,20-MIN(20,INT(J4/K4*20))))) | N4: =IF(J4=0,"⬜",IF(J4/K4<0.8,"🟢",IF(J4/K4<=1,"🟡","🔴")))
B5: 🛒 Alimentation | C5: 0 | D5: 0 | E5: 0 | F5: 0 | G5: 0 | H5: 0 | I5: 0 | J5: =SUM(C5:I5) | K5: 104 | L5: =IF(K5=0,0,J5/K5) | M5: =IF(K5=0,"—",REPT("▓",MIN(20,INT(J5/K5*20)))&REPT("░",MAX(0,20-MIN(20,INT(J5/K5*20))))) | N5: =IF(J5=0,"⬜",IF(J5/K5<0.8,"🟢",IF(J5/K5<=1,"🟡","🔴")))
B6: 🚗 Transport | C6: 0 | D6: 0 | E6: 0 | F6: 0 | G6: 0 | H6: 0 | I6: 0 | J6: =SUM(C6:I6) | K6: 46 | L6: =IF(K6=0,0,J6/K6) | M6: =IF(K6=0,"—",REPT("▓",MIN(20,INT(J6/K6*20)))&REPT("░",MAX(0,20-MIN(20,INT(J6/K6*20))))) | N6: =IF(J6=0,"⬜",IF(J6/K6<0.8,"🟢",IF(J6/K6<=1,"🟡","🔴")))
B7: 💊 Santé | C7: 0 | D7: 0 | E7: 0 | F7: 0 | G7: 0 | H7: 0 | I7: 0 | J7: =SUM(C7:I7) | K7: 23 | L7: =IF(K7=0,0,J7/K7) | M7: =IF(K7=0,"—",REPT("▓",MIN(20,INT(J7/K7*20)))&REPT("░",MAX(0,20-MIN(20,INT(J7/K7*20))))) | N7: =IF(J7=0,"⬜",IF(J7/K7<0.8,"🟢",IF(J7/K7<=1,"🟡","🔴")))
B8: 🎮 Loisirs | C8: 0 | D8: 0 | E8: 0 | F8: 0 | G8: 0 | H8: 0 | I8: 0 | J8: =SUM(C8:I8) | K8: 35 | L8: =IF(K8=0,0,J8/K8) | M8: =IF(K8=0,"—",REPT("▓",MIN(20,INT(J8/K8*20)))&REPT("░",MAX(0,20-MIN(20,INT(J8/K8*20))))) | N8: =IF(J8=0,"⬜",IF(J8/K8<0.8,"🟢",IF(J8/K8<=1,"🟡","🔴")))
B9: 📱 Abonnements | C9: 0 | D9: 0 | E9: 0 | F9: 0 | G9: 0 | H9: 0 | I9: 0 | J9: =SUM(C9:I9) | K9: 14 | L9: =IF(K9=0,0,J9/K9) | M9: =IF(K9=0,"—",REPT("▓",MIN(20,INT(J9/K9*20)))&REPT("░",MAX(0,20-MIN(20,INT(J9/K9*20))))) | N9: =IF(J9=0,"⬜",IF(J9/K9<0.8,"🟢",IF(J9/K9<=1,"🟡","🔴")))
B10: 👗 Shopping | C10: 0 | D10: 0 | E10: 0 | F10: 0 | G10: 0 | H10: 0 | I10: 0 | J10: =SUM(C10:I10) | K10: 28 | L10: =IF(K10=0,0,J10/K10) | M10: =IF(K10=0,"—",REPT("▓",MIN(20,INT(J10/K10*20)))&REPT("░",MAX(0,20-MIN(20,INT(J10/K10*20))))) | N10: =IF(J10=0,"⬜",IF(J10/K10<0.8,"🟢",IF(J10/K10<=1,"🟡","🔴")))
B11: 💡 Divers | C11: 0 | D11: 0 | E11: 0 | F11: 0 | G11: 0 | H11: 0 | I11: 0 | J11: =SUM(C11:I11) | K11: 18 | L11: =IF(K11=0,0,J11/K11) | M11: =IF(K11=0,"—",REPT("▓",MIN(20,INT(J11/K11*20)))&REPT("░",MAX(0,20-MIN(20,INT(J11/K11*20))))) | N11: =IF(J11=0,"⬜",IF(J11/K11<0.8,"🟢",IF(J11/K11<=1,"🟡","🔴")))
B12: TOTAL SEMAINE | C12: =SUM(C4:C11) | D12: =SUM(D4:D11) | E12: =SUM(E4:E11) | F12: =SUM(F4:F11) | G12: =SUM(G4:G11) | H12: =SUM(H4:H11) | I12: =SUM(I4:I11) | J12: =SUM(J4:J11) | K12: =SUM(K4:K11) | L12: =IF(K12=0,0,J12/K12) | M12: =IF(K12=0,"—",REPT("▓",MIN(20,INT(J12/K12*20)))&REPT("░",MAX(0,20-MIN(20,INT(J12/K12*20))))) | N12: =IF(J12=0,"⬜",IF(J12/K12<0.8,"🟢",IF(J12/K12<=1,"🟡","🔴")))

Sheet S03
B2: 📅 SEMAINE 03 — Suivi de dépenses hebdomadaire
B3: Catégorie | C3: Lun | D3: Mar | E3: Mer | F3: Jeu | G3: Ven | H3: Sam | I3: Dim | J3: Total sem. | K3: Budget sem. | L3: % utilisé | M3: ▓▓▓ Progression | N3: 🚦
B4: 🏠 Logement | C4: 0 | D4: 0 | E4: 0 | F4: 0 | G4: 0 | H4: 0 | I4: 0 | J4: =SUM(C4:I4) | K4: 207 | L4: =IF(K4=0,0,J4/K4) | M4: =IF(K4=0,"—",REPT("▓",MIN(20,INT(J4/K4*20)))&REPT("░",MAX(0,20-MIN(20,INT(J4/K4*20))))) | N4: =IF(J4=0,"⬜",IF(J4/K4<0.8,"🟢",IF(J4/K4<=1,"🟡","🔴")))
B5: 🛒 Alimentation | C5: 0 | D5: 0 | E5: 0 | F5: 0 | G5: 0 | H5: 0 | I5: 0 | J5: =SUM(C5:I5) | K5: 104 | L5: =IF(K5=0,0,J5/K5) | M5: =IF(K5=0,"—",REPT("▓",MIN(20,INT(J5/K5*20)))&REPT("░",MAX(0,20-MIN(20,INT(J5/K5*20))))) | N5: =IF(J5=0,"⬜",IF(J5/K5<0.8,"🟢",IF(J5/K5<=1,"🟡","🔴")))
B6: 🚗 Transport | C6: 0 | D6: 0 | E6: 0 | F6: 0 | G6: 0 | H6: 0 | I6: 0 | J6: =SUM(C6:I6) | K6: 46 | L6: =IF(K6=0,0,J6/K6) | M6: =IF(K6=0,"—",REPT("▓",MIN(20,INT(J6/K6*20)))&REPT("░",MAX(0,20-MIN(20,INT(J6/K6*20))))) | N6: =IF(J6=0,"⬜",IF(J6/K6<0.8,"🟢",IF(J6/K6<=1,"🟡","🔴")))
B7: 💊 Santé | C7: 0 | D7: 0 | E7: 0 | F7: 0 | G7: 0 | H7: 0 | I7: 0 | J7: =SUM(C7:I7) | K7: 23 | L7: =IF(K7=0,0,J7/K7) | M7: =IF(K7=0,"—",REPT("▓",MIN(20,INT(J7/K7*20)))&REPT("░",MAX(0,20-MIN(20,INT(J7/K7*20))))) | N7: =IF(J7=0,"⬜",IF(J7/K7<0.8,"🟢",IF(J7/K7<=1,"🟡","🔴")))
B8: 🎮 Loisirs | C8: 0 | D8: 0 | E8: 0 | F8: 0 | G8: 0 | H8: 0 | I8: 0 | J8: =SUM(C8:I8) | K8: 35 | L8: =IF(K8=0,0,J8/K8) | M8: =IF(K8=0,"—",REPT("▓",MIN(20,INT(J8/K8*20)))&REPT("░",MAX(0,20-MIN(20,INT(J8/K8*20))))) | N8: =IF(J8=0,"⬜",IF(J8/K8<0.8,"🟢",IF(J8/K8<=1,"🟡","🔴")))
B9: 📱 Abonnements | C9: 0 | D9: 0 | E9: 0 | F9: 0 | G9: 0 | H9: 0 | I9: 0 | J9: =SUM(C9:I9) | K9: 14 | L9: =IF(K9=0,0,J9/K9) | M9: =IF(K9=0,"—",REPT("▓",MIN(20,INT(J9/K9*20)))&REPT("░",MAX(0,20-MIN(20,INT(J9/K9*20))))) | N9: =IF(J9=0,"⬜",IF(J9/K9<0.8,"🟢",IF(J9/K9<=1,"🟡","🔴")))
B10: 👗 Shopping | C10: 0 | D10: 0 | E10: 0 | F10: 0 | G10: 0 | H10: 0 | I10: 0 | J10: =SUM(C10:I10) | K10: 28 | L10: =IF(K10=0,0,J10/K10) | M10: =IF(K10=0,"—",REPT("▓",MIN(20,INT(J10/K10*20)))&REPT("░",MAX(0,20-MIN(20,INT(J10/K10*20))))) | N10: =IF(J10=0,"⬜",IF(J10/K10<0.8,"🟢",IF(J10/K10<=1,"🟡","🔴")))
B11: 💡 Divers | C11: 0 | D11: 0 | E11: 0 | F11: 0 | G11: 0 | H11: 0 | I11: 0 | J11: =SUM(C11:I11) | K11: 18 | L11: =IF(K11=0,0,J11/K11) | M11: =IF(K11=0,"—",REPT("▓",MIN(20,INT(J11/K11*20)))&REPT("░",MAX(0,20-MIN(20,INT(J11/K11*20))))) | N11: =IF(J11=0,"⬜",IF(J11/K11<0.8,"🟢",IF(J11/K11<=1,"🟡","🔴")))
B12: TOTAL SEMAINE | C12: =SUM(C4:C11) | D12: =SUM(D4:D11) | E12: =SUM(E4:E11) | F12: =SUM(F4:F11) | G12: =SUM(G4:G11) | H12: =SUM(H4:H11) | I12: =SUM(I4:I11) | J12: =SUM(J4:J11) | K12: =SUM(K4:K11) | L12: =IF(K12=0,0,J12/K12) | M12: =IF(K12=0,"—",REPT("▓",MIN(20,INT(J12/K12*20)))&REPT("░",MAX(0,20-MIN(20,INT(J12/K12*20))))) | N12: =IF(J12=0,"⬜",IF(J12/K12<0.8,"🟢",IF(J12/K12<=1,"🟡","🔴")))

Sheet S04
B2: 📅 SEMAINE 04 — Suivi de dépenses hebdomadaire
B3: Catégorie | C3: Lun | D3: Mar | E3: Mer | F3: Jeu | G3: Ven | H3: Sam | I3: Dim | J3: Total sem. | K3: Budget sem. | L3: % utilisé | M3: ▓▓▓ Progression | N3: 🚦
B4: 🏠 Logement | C4: 0 | D4: 0 | E4: 0 | F4: 0 | G4: 0 | H4: 0 | I4: 0 | J4: =SUM(C4:I4) | K4: 207 | L4: =IF(K4=0,0,J4/K4) | M4: =IF(K4=0,"—",REPT("▓",MIN(20,INT(J4/K4*20)))&REPT("░",MAX(0,20-MIN(20,INT(J4/K4*20))))) | N4: =IF(J4=0,"⬜",IF(J4/K4<0.8,"🟢",IF(J4/K4<=1,"🟡","🔴")))
B5: 🛒 Alimentation | C5: 0 | D5: 0 | E5: 0 | F5: 0 | G5: 0 | H5: 0 | I5: 0 | J5: =SUM(C5:I5) | K5: 104 | L5: =IF(K5=0,0,J5/K5) | M5: =IF(K5=0,"—",REPT("▓",MIN(20,INT(J5/K5*20)))&REPT("░",MAX(0,20-MIN(20,INT(J5/K5*20))))) | N5: =IF(J5=0,"⬜",IF(J5/K5<0.8,"🟢",IF(J5/K5<=1,"🟡","🔴")))
B6: 🚗 Transport | C6: 0 | D6: 0 | E6: 0 | F6: 0 | G6: 0 | H6: 0 | I6: 0 | J6: =SUM(C6:I6) | K6: 46 | L6: =IF(K6=0,0,J6/K6) | M6: =IF(K6=0,"—",REPT("▓",MIN(20,INT(J6/K6*20)))&REPT("░",MAX(0,20-MIN(20,INT(J6/K6*20))))) | N6: =IF(J6=0,"⬜",IF(J6/K6<0.8,"🟢",IF(J6/K6<=1,"🟡","🔴")))
B7: 💊 Santé | C7: 0 | D7: 0 | E7: 0 | F7: 0 | G7: 0 | H7: 0 | I7: 0 | J7: =SUM(C7:I7) | K7: 23 | L7: =IF(K7=0,0,J7/K7) | M7: =IF(K7=0,"—",REPT("▓",MIN(20,INT(J7/K7*20)))&REPT("░",MAX(0,20-MIN(20,INT(J7/K7*20))))) | N7: =IF(J7=0,"⬜",IF(J7/K7<0.8,"🟢",IF(J7/K7<=1,"🟡","🔴")))
B8: 🎮 Loisirs | C8: 0 | D8: 0 | E8: 0 | F8: 0 | G8: 0 | H8: 0 | I8: 0 | J8: =SUM(C8:I8) | K8: 35 | L8: =IF(K8=0,0,J8/K8) | M8: =IF(K8=0,"—",REPT("▓",MIN(20,INT(J8/K8*20)))&REPT("░",MAX(0,20-MIN(20,INT(J8/K8*20))))) | N8: =IF(J8=0,"⬜",IF(J8/K8<0.8,"🟢",IF(J8/K8<=1,"🟡","🔴")))
B9: 📱 Abonnements | C9: 0 | D9: 0 | E9: 0 | F9: 0 | G9: 0 | H9: 0 | I9: 0 | J9: =SUM(C9:I9) | K9: 14 | L9: =IF(K9=0,0,J9/K9) | M9: =IF(K9=0,"—",REPT("▓",MIN(20,INT(J9/K9*20)))&REPT("░",MAX(0,20-MIN(20,INT(J9/K9*20))))) | N9: =IF(J9=0,"⬜",IF(J9/K9<0.8,"🟢",IF(J9/K9<=1,"🟡","🔴")))
B10: 👗 Shopping | C10: 0 | D10: 0 | E10: 0 | F10: 0 | G10: 0 | H10: 0 | I10: 0 | J10: =SUM(C10:I10) | K10: 28 | L10: =IF(K10=0,0,J10/K10) | M10: =IF(K10=0,"—",REPT("▓",MIN(20,INT(J10/K10*20)))&REPT("░",MAX(0,20-MIN(20,INT(J10/K10*20))))) | N10: =IF(J10=0,"⬜",IF(J10/K10<0.8,"🟢",IF(J10/K10<=1,"🟡","🔴")))
B11: 💡 Divers | C11: 0 | D11: 0 | E11: 0 | F11: 0 | G11: 0 | H11: 0 | I11: 0 | J11: =SUM(C11:I11) | K11: 18 | L11: =IF(K11=0,0,J11/K11) | M11: =IF(K11=0,"—",REPT("▓",MIN(20,INT(J11/K11*20)))&REPT("░",MAX(0,20-MIN(20,INT(J11/K11*20))))) | N11: =IF(J11=0,"⬜",IF(J11/K11<0.8,"🟢",IF(J11/K11<=1,"🟡","🔴")))
B12: TOTAL SEMAINE | C12: =SUM(C4:C11) | D12: =SUM(D4:D11) | E12: =SUM(E4:E11) | F12: =SUM(F4:F11) | G12: =SUM(G4:G11) | H12: =SUM(H4:H11) | I12: =SUM(I4:I11) | J12: =SUM(J4:J11) | K12: =SUM(K4:K11) | L12: =IF(K12=0,0,J12/K12) | M12: =IF(K12=0,"—",REPT("▓",MIN(20,INT(J12/K12*20)))&REPT("░",MAX(0,20-MIN(20,INT(J12/K12*20))))) | N12: =IF(J12=0,"⬜",IF(J12/K12<0.8,"🟢",IF(J12/K12<=1,"🟡","🔴")))

Sheet S05
B2: 📅 SEMAINE 05 — Suivi de dépenses hebdomadaire
B3: Catégorie | C3: Lun | D3: Mar | E3: Mer | F3: Jeu | G3: Ven | H3: Sam | I3: Dim | J3: Total sem. | K3: Budget sem. | L3: % utilisé | M3: ▓▓▓ Progression | N3: 🚦
B4: 🏠 Logement | C4: 0 | D4: 0 | E4: 0 | F4: 0 | G4: 0 | H4: 0 | I4: 0 | J4: =SUM(C4:I4) | K4: 207 | L4: =IF(K4=0,0,J4/K4) | M4: =IF(K4=0,"—",REPT("▓",MIN(20,INT(J4/K4*20)))&REPT("░",MAX(0,20-MIN(20,INT(J4/K4*20))))) | N4: =IF(J4=0,"⬜",IF(J4/K4<0.8,"🟢",IF(J4/K4<=1,"🟡","🔴")))
B5: 🛒 Alimentation | C5: 0 | D5: 0 | E5: 0 | F5: 0 | G5: 0 | H5: 0 | I5: 0 | J5: =SUM(C5:I5) | K5: 104 | L5: =IF(K5=0,0,J5/K5) | M5: =IF(K5=0,"—",REPT("▓",MIN(20,INT(J5/K5*20)))&REPT("░",MAX(0,20-MIN(20,INT(J5/K5*20))))) | N5: =IF(J5=0,"⬜",IF(J5/K5<0.8,"🟢",IF(J5/K5<=1,"🟡","🔴")))
B6: 🚗 Transport | C6: 0 | D6: 0 | E6: 0 | F6: 0 | G6: 0 | H6: 0 | I6: 0 | J6: =SUM(C6:I6) | K6: 46 | L6: =IF(K6=0,0,J6/K6) | M6: =IF(K6=0,"—",REPT("▓",MIN(20,INT(J6/K6*20)))&REPT("░",MAX(0,20-MIN(20,INT(J6/K6*20))))) | N6: =IF(J6=0,"⬜",IF(J6/K6<0.8,"🟢",IF(J6/K6<=1,"🟡","🔴")))
B7: 💊 Santé | C7: 0 | D7: 0 | E7: 0 | F7: 0 | G7: 0 | H7: 0 | I7: 0 | J7: =SUM(C7:I7) | K7: 23 | L7: =IF(K7=0,0,J7/K7) | M7: =IF(K7=0,"—",REPT("▓",MIN(20,INT(J7/K7*20)))&REPT("░",MAX(0,20-MIN(20,INT(J7/K7*20))))) | N7: =IF(J7=0,"⬜",IF(J7/K7<0.8,"🟢",IF(J7/K7<=1,"🟡","🔴")))
B8: 🎮 Loisirs | C8: 0 | D8: 0 | E8: 0 | F8: 0 | G8: 0 | H8: 0 | I8: 0 | J8: =SUM(C8:I8) | K8: 35 | L8: =IF(K8=0,0,J8/K8) | M8: =IF(K8=0,"—",REPT("▓",MIN(20,INT(J8/K8*20)))&REPT("░",MAX(0,20-MIN(20,INT(J8/K8*20))))) | N8: =IF(J8=0,"⬜",IF(J8/K8<0.8,"🟢",IF(J8/K8<=1,"🟡","🔴")))
B9: 📱 Abonnements | C9: 0 | D9: 0 | E9: 0 | F9: 0 | G9: 0 | H9: 0 | I9: 0 | J9: =SUM(C9:I9) | K9: 14 | L9: =IF(K9=0,0,J9/K9) | M9: =IF(K9=0,"—",REPT("▓",MIN(20,INT(J9/K9*20)))&REPT("░",MAX(0,20-MIN(20,INT(J9/K9*20))))) | N9: =IF(J9=0,"⬜",IF(J9/K9<0.8,"🟢",IF(J9/K9<=1,"🟡","🔴")))
B10: 👗 Shopping | C10: 0 | D10: 0 | E10: 0 | F10: 0 | G10: 0 | H10: 0 | I10: 0 | J10: =SUM(C10:I10) | K10: 28 | L10: =IF(K10=0,0,J10/K10) | M10: =IF(K10=0,"—",REPT("▓",MIN(20,INT(J10/K10*20)))&REPT("░",MAX(0,20-MIN(20,INT(J10/K10*20))))) | N10: =IF(J10=0,"⬜",IF(J10/K10<0.8,"🟢",IF(J10/K10<=1,"🟡","🔴")))
B11: 💡 Divers | C11: 0 | D11: 0 | E11: 0 | F11: 0 | G11: 0 | H11: 0 | I11: 0 | J11: =SUM(C11:I11) | K11: 18 | L11: =IF(K11=0,0,J11/K11) | M11: =IF(K11=0,"—",REPT("▓",MIN(20,INT(J11/K11*20)))&REPT("░",MAX(0,20-MIN(20,INT(J11/K11*20))))) | N11: =IF(J11=0,"⬜",IF(J11/K11<0.8,"🟢",IF(J11/K11<=1,"🟡","🔴")))
B12: TOTAL SEMAINE | C12: =SUM(C4:C11) | D12: =SUM(D4:D11) | E12: =SUM(E4:E11) | F12: =SUM(F4:F11) | G12: =SUM(G4:G11) | H12: =SUM(H4:H11) | I12: =SUM(I4:I11) | J12: =SUM(J4:J11) | K12: =SUM(K4:K11) | L12: =IF(K12=0,0,J12/K12) | M12: =IF(K12=0,"—",REPT("▓",MIN(20,INT(J12/K12*20)))&REPT("░",MAX(0,20-MIN(20,INT(J12/K12*20))))) | N12: =IF(J12=0,"⬜",IF(J12/K12<0.8,"🟢",IF(J12/K12<=1,"🟡","🔴")))

Sheet S06
B2: 📅 SEMAINE 06 — Suivi de dépenses hebdomadaire
B3: Catégorie | C3: Lun | D3: Mar | E3: Mer | F3: Jeu | G3: Ven | H3: Sam | I3: Dim | J3: Total sem. | K3: Budget sem. | L3: % utilisé | M3: ▓▓▓ Progression | N3: 🚦
B4: 🏠 Logement | C4: 0 | D4: 0 | E4: 0 | F4: 0 | G4: 0 | H4: 0 | I4: 0 | J4: =SUM(C4:I4) | K4: 207 | L4: =IF(K4=0,0,J4/K4) | M4: =IF(K4=0,"—",REPT("▓",MIN(20,INT(J4/K4*20)))&REPT("░",MAX(0,20-MIN(20,INT(J4/K4*20))))) | N4: =IF(J4=0,"⬜",IF(J4/K4<0.8,"🟢",IF(J4/K4<=1,"🟡","🔴")))
B5: 🛒 Alimentation | C5: 0 | D5: 0 | E5: 0 | F5: 0 | G5: 0 | H5: 0 | I5: 0 | J5: =SUM(C5:I5) | K5: 104 | L5: =IF(K5=0,0,J5/K5) | M5: =IF(K5=0,"—",REPT("▓",MIN(20,INT(J5/K5*20)))&REPT("░",MAX(0,20-MIN(20,INT(J5/K5*20))))) | N5: =IF(J5=0,"⬜",IF(J5/K5<0.8,"🟢",IF(J5/K5<=1,"🟡","🔴")))
B6: 🚗 Transport | C6: 0 | D6: 0 | E6: 0 | F6: 0 | G6: 0 | H6: 0 | I6: 0 | J6: =SUM(C6:I6) | K6: 46 | L6: =IF(K6=0,0,J6/K6) | M6: =IF(K6=0,"—",REPT("▓",MIN(20,INT(J6/K6*20)))&REPT("░",MAX(0,20-MIN(20,INT(J6/K6*20))))) | N6: =IF(J6=0,"⬜",IF(J6/K6<0.8,"🟢",IF(J6/K6<=1,"🟡","🔴")))
B7: 💊 Santé | C7: 0 | D7: 0 | E7: 0 | F7: 0 | G7: 0 | H7: 0 | I7: 0 | J7: =SUM(C7:I7) | K7: 23 | L7: =IF(K7=0,0,J7/K7) | M7: =IF(K7=0,"—",REPT("▓",MIN(20,INT(J7/K7*20)))&REPT("░",MAX(0,20-MIN(20,INT(J7/K7*20))))) | N7: =IF(J7=0,"⬜",IF(J7/K7<0.8,"🟢",IF(J7/K7<=1,"🟡","🔴")))
B8: 🎮 Loisirs | C8: 0 | D8: 0 | E8: 0 | F8: 0 | G8: 0 | H8: 0 | I8: 0 | J8: =SUM(C8:I8) | K8: 35 | L8: =IF(K8=0,0,J8/K8) | M8: =IF(K8=0,"—",REPT("▓",MIN(20,INT(J8/K8*20)))&REPT("░",MAX(0,20-MIN(20,INT(J8/K8*20))))) | N8: =IF(J8=0,"⬜",IF(J8/K8<0.8,"🟢",IF(J8/K8<=1,"🟡","🔴")))
B9: 📱 Abonnements | C9: 0 | D9: 0 | E9: 0 | F9: 0 | G9: 0 | H9: 0 | I9: 0 | J9: =SUM(C9:I9) | K9: 14 | L9: =IF(K9=0,0,J9/K9) | M9: =IF(K9=0,"—",REPT("▓",MIN(20,INT(J9/K9*20)))&REPT("░",MAX(0,20-MIN(20,INT(J9/K9*20))))) | N9: =IF(J9=0,"⬜",IF(J9/K9<0.8,"🟢",IF(J9/K9<=1,"🟡","🔴")))
B10: 👗 Shopping | C10: 0 | D10: 0 | E10: 0 | F10: 0 | G10: 0 | H10: 0 | I10: 0 | J10: =SUM(C10:I10) | K10: 28 | L10: =IF(K10=0,0,J10/K10) | M10: =IF(K10=0,"—",REPT("▓",MIN(20,INT(J10/K10*20)))&REPT("░",MAX(0,20-MIN(20,INT(J10/K10*20))))) | N10: =IF(J10=0,"⬜",IF(J10/K10<0.8,"🟢",IF(J10/K10<=1,"🟡","🔴")))
B11: 💡 Divers | C11: 0 | D11: 0 | E11: 0 | F11: 0 | G11: 0 | H11: 0 | I11: 0 | J11: =SUM(C11:I11) | K11: 18 | L11: =IF(K11=0,0,J11/K11) | M11: =IF(K11=0,"—",REPT("▓",MIN(20,INT(J11/K11*20)))&REPT("░",MAX(0,20-MIN(20,INT(J11/K11*20))))) | N11: =IF(J11=0,"⬜",IF(J11/K11<0.8,"🟢",IF(J11/K11<=1,"🟡","🔴")))
B12: TOTAL SEMAINE | C12: =SUM(C4:C11) | D12: =SUM(D4:D11) | E12: =SUM(E4:E11) | F12: =SUM(F4:F11) | G12: =SUM(G4:G11) | H12: =SUM(H4:H11) | I12: =SUM(I4:I11) | J12: =SUM(J4:J11) | K12: =SUM(K4:K11) | L12: =IF(K12=0,0,J12/K12) | M12: =IF(K12=0,"—",REPT("▓",MIN(20,INT(J12/K12*20)))&REPT("░",MAX(0,20-MIN(20,INT(J12/K12*20))))) | N12: =IF(J12=0,"⬜",IF(J12/K12<0.8,"🟢",IF(J12/K12<=1,"🟡","🔴")))

Sheet S07
B2: 📅 SEMAINE 07 — Suivi de dépenses hebdomadaire
B3: Catégorie | C3: Lun | D3: Mar | E3: Mer | F3: Jeu | G3: Ven | H3: Sam | I3: Dim | J3: Total sem. | K3: Budget sem. | L3: % utilisé | M3: ▓▓▓ Progression | N3: 🚦
B4: 🏠 Logement | C4: 0 | D4: 0 | E4: 0 | F4: 0 | G4: 0 | H4: 0 | I4: 0 | J4: =SUM(C4:I4) | K4: 207 | L4: =IF(K4=0,0,J4/K4) | M4: =IF(K4=0,"—",REPT("▓",MIN(20,INT(J4/K4*20)))&REPT("░",MAX(0,20-MIN(20,INT(J4/K4*20))))) | N4: =IF(J4=0,"⬜",IF(J4/K4<0.8,"🟢",IF(J4/K4<=1,"🟡","🔴")))
B5: 🛒 Alimentation | C5: 0 | D5: 0 | E5: 0 | F5: 0 | G5: 0 | H5: 0 | I5: 0 | J5: =SUM(C5:I5) | K5: 104 | L5: =IF(K5=0,0,J5/K5) | M5: =IF(K5=0,"—",REPT("▓",MIN(20,INT(J5/K5*20)))&REPT("░",MAX(0,20-MIN(20,INT(J5/K5*20))))) | N5: =IF(J5=0,"⬜",IF(J5/K5<0.8,"🟢",IF(J5/K5<=1,"🟡","🔴")))
B6: 🚗 Transport | C6: 0 | D6: 0 | E6: 0 | F6: 0 | G6: 0 | H6: 0 | I6: 0 | J6: =SUM(C6:I6) | K6: 46 | L6: =IF(K6=0,0,J6/K6) | M6: =IF(K6=0,"—",REPT("▓",MIN(20,INT(J6/K6*20)))&REPT("░",MAX(0,20-MIN(20,INT(J6/K6*20))))) | N6: =IF(J6=0,"⬜",IF(J6/K6<0.8,"🟢",IF(J6/K6<=1,"🟡","🔴")))
B7: 💊 Santé | C7: 0 | D7: 0 | E7: 0 | F7: 0 | G7: 0 | H7: 0 | I7: 0 | J7: =SUM(C7:I7) | K7: 23 | L7: =IF(K7=0,0,J7/K7) | M7: =IF(K7=0,"—",REPT("▓",MIN(20,INT(J7/K7*20)))&REPT("░",MAX(0,20-MIN(20,INT(J7/K7*20))))) | N7: =IF(J7=0,"⬜",IF(J7/K7<0.8,"🟢",IF(J7/K7<=1,"🟡","🔴")))
B8: 🎮 Loisirs | C8: 0 | D8: 0 | E8: 0 | F8: 0 | G8: 0 | H8: 0 | I8: 0 | J8: =SUM(C8:I8) | K8: 35 | L8: =IF(K8=0,0,J8/K8) | M8: =IF(K8=0,"—",REPT("▓",MIN(20,INT(J8/K8*20)))&REPT("░",MAX(0,20-MIN(20,INT(J8/K8*20))))) | N8: =IF(J8=0,"⬜",IF(J8/K8<0.8,"🟢",IF(J8/K8<=1,"🟡","🔴")))
B9: 📱 Abonnements | C9: 0 | D9: 0 | E9: 0 | F9: 0 | G9: 0 | H9: 0 | I9: 0 | J9: =SUM(C9:I9) | K9: 14 | L9: =IF(K9=0,0,J9/K9) | M9: =IF(K9=0,"—",REPT("▓",MIN(20,INT(J9/K9*20)))&REPT("░",MAX(0,20-MIN(20,INT(J9/K9*20))))) | N9: =IF(J9=0,"⬜",IF(J9/K9<0.8,"🟢",IF(J9/K9<=1,"🟡","🔴")))
B10: 👗 Shopping | C10: 0 | D10: 0 | E10: 0 | F10: 0 | G10: 0 | H10: 0 | I10: 0 | J10: =SUM(C10:I10) | K10: 28 | L10: =IF(K10=0,0,J10/K10) | M10: =IF(K10=0,"—",REPT("▓",MIN(20,INT(J10/K10*20)))&REPT("░",MAX(0,20-MIN(20,INT(J10/K10*20))))) | N10: =IF(J10=0,"⬜",IF(J10/K10<0.8,"🟢",IF(J10/K10<=1,"🟡","🔴")))
B11: 💡 Divers | C11: 0 | D11: 0 | E11: 0 | F11: 0 | G11: 0 | H11: 0 | I11: 0 | J11: =SUM(C11:I11) | K11: 18 | L11: =IF(K11=0,0,J11/K11) | M11: =IF(K11=0,"—",REPT("▓",MIN(20,INT(J11/K11*20)))&REPT("░",MAX(0,20-MIN(20,INT(J11/K11*20))))) | N11: =IF(J11=0,"⬜",IF(J11/K11<0.8,"🟢",IF(J11/K11<=1,"🟡","🔴")))
B12: TOTAL SEMAINE | C12: =SUM(C4:C11) | D12: =SUM(D4:D11) | E12: =SUM(E4:E11) | F12: =SUM(F4:F11) | G12: =SUM(G4:G11) | H12: =SUM(H4:H11) | I12: =SUM(I4:I11) | J12: =SUM(J4:J11) | K12: =SUM(K4:K11) | L12: =IF(K12=0,0,J12/K12) | M12: =IF(K12=0,"—",REPT("▓",MIN(20,INT(J12/K12*20)))&REPT("░",MAX(0,20-MIN(20,INT(J12/K12*20))))) | N12: =IF(J12=0,"⬜",IF(J12/K12<0.8,"🟢",IF(J12/K12<=1,"🟡","🔴")))

Sheet S08
B2: 📅 SEMAINE 08 — Suivi de dépenses hebdomadaire
B3: Catégorie | C3: Lun | D3: Mar | E3: Mer | F3: Jeu | G3: Ven | H3: Sam | I3: Dim | J3: Total sem. | K3: Budget sem. | L3: % utilisé | M3: ▓▓▓ Progression | N3: 🚦
B4: 🏠 Logement | C4: 0 | D4: 0 | E4: 0 | F4: 0 | G4: 0 | H4: 0 | I4: 0 | J4: =SUM(C4:I4) | K4: 207 | L4: =IF(K4=0,0,J4/K4) | M4: =IF(K4=0,"—",REPT("▓",MIN(20,INT(J4/K4*20)))&REPT("░",MAX(0,20-MIN(20,INT(J4/K4*20))))) | N4: =IF(J4=0,"⬜",IF(J4/K4<0.8,"🟢",IF(J4/K4<=1,"🟡","🔴")))
B5: 🛒 Alimentation | C5: 0 | D5: 0 | E5: 0 | F5: 0 | G5: 0 | H5: 0 | I5: 0 | J5: =SUM(C5:I5) | K5: 104 | L5: =IF(K5=0,0,J5/K5) | M5: =IF(K5=0,"—",REPT("▓",MIN(20,INT(J5/K5*20)))&REPT("░",MAX(0,20-MIN(20,INT(J5/K5*20))))) | N5: =IF(J5=0,"⬜",IF(J5/K5<0.8,"🟢",IF(J5/K5<=1,"🟡","🔴")))
B6: 🚗 Transport | C6: 0 | D6: 0 | E6: 0 | F6: 0 | G6: 0 | H6: 0 | I6: 0 | J6: =SUM(C6:I6) | K6: 46 | L6: =IF(K6=0,0,J6/K6) | M6: =IF(K6=0,"—",REPT("▓",MIN(20,INT(J6/K6*20)))&REPT("░",MAX(0,20-MIN(20,INT(J6/K6*20))))) | N6: =IF(J6=0,"⬜",IF(J6/K6<0.8,"🟢",IF(J6/K6<=1,"🟡","🔴")))
B7: 💊 Santé | C7: 0 | D7: 0 | E7: 0 | F7: 0 | G7: 0 | H7: 0 | I7: 0 | J7: =SUM(C7:I7) | K7: 23 | L7: =IF(K7=0,0,J7/K7) | M7: =IF(K7=0,"—",REPT("▓",MIN(20,INT(J7/K7*20)))&REPT("░",MAX(0,20-MIN(20,INT(J7/K7*20))))) | N7: =IF(J7=0,"⬜",IF(J7/K7<0.8,"🟢",IF(J7/K7<=1,"🟡","🔴")))
B8: 🎮 Loisirs | C8: 0 | D8: 0 | E8: 0 | F8: 0 | G8: 0 | H8: 0 | I8: 0 | J8: =SUM(C8:I8) | K8: 35 | L8: =IF(K8=0,0,J8/K8) | M8: =IF(K8=0,"—",REPT("▓",MIN(20,INT(J8/K8*20)))&REPT("░",MAX(0,20-MIN(20,INT(J8/K8*20))))) | N8: =IF(J8=0,"⬜",IF(J8/K8<0.8,"🟢",IF(J8/K8<=1,"🟡","🔴")))
B9: 📱 Abonnements | C9: 0 | D9: 0 | E9: 0 | F9: 0 | G9: 0 | H9: 0 | I9: 0 | J9: =SUM(C9:I9) | K9: 14 | L9: =IF(K9=0,0,J9/K9) | M9: =IF(K9=0,"—",REPT("▓",MIN(20,INT(J9/K9*20)))&REPT("░",MAX(0,20-MIN(20,INT(J9/K9*20))))) | N9: =IF(J9=0,"⬜",IF(J9/K9<0.8,"🟢",IF(J9/K9<=1,"🟡","🔴")))
B10: 👗 Shopping | C10: 0 | D10: 0 | E10: 0 | F10: 0 | G10: 0 | H10: 0 | I10: 0 | J10: =SUM(C10:I10) | K10: 28 | L10: =IF(K10=0,0,J10/K10) | M10: =IF(K10=0,"—",REPT("▓",MIN(20,INT(J10/K10*20)))&REPT("░",MAX(0,20-MIN(20,INT(J10/K10*20))))) | N10: =IF(J10=0,"⬜",IF(J10/K10<0.8,"🟢",IF(J10/K10<=1,"🟡","🔴")))
B11: 💡 Divers | C11: 0 | D11: 0 | E11: 0 | F11: 0 | G11: 0 | H11: 0 | I11: 0 | J11: =SUM(C11:I11) | K11: 18 | L11: =IF(K11=0,0,J11/K11) | M11: =IF(K11=0,"—",REPT("▓",MIN(20,INT(J11/K11*20)))&REPT("░",MAX(0,20-MIN(20,INT(J11/K11*20))))) | N11: =IF(J11=0,"⬜",IF(J11/K11<0.8,"🟢",IF(J11/K11<=1,"🟡","🔴")))
B12: TOTAL SEMAINE | C12: =SUM(C4:C11) | D12: =SUM(D4:D11) | E12: =SUM(E4:E11) | F12: =SUM(F4:F11) | G12: =SUM(G4:G11) | H12: =SUM(H4:H11) | I12: =SUM(I4:I11) | J12: =SUM(J4:J11) | K12: =SUM(K4:K11) | L12: =IF(K12=0,0,J12/K12) | M12: =IF(K12=0,"—",REPT("▓",MIN(20,INT(J12/K12*20)))&REPT("░",MAX(0,20-MIN(20,INT(J12/K12*20))))) | N12: =IF(J12=0,"⬜",IF(J12/K12<0.8,"🟢",IF(J12/K12<=1,"🟡","🔴")))

Sheet S09
B2: 📅 SEMAINE 09 — Suivi de dépenses hebdomadaire
B3: Catégorie | C3: Lun | D3: Mar | E3: Mer | F3: Jeu | G3: Ven | H3: Sam | I3: Dim | J3: Total sem. | K3: Budget sem. | L3: % utilisé | M3: ▓▓▓ Progression | N3: 🚦
B4: 🏠 Logement | C4: 0 | D4: 0 | E4: 0 | F4: 0 | G4: 0 | H4: 0 | I4: 0 | J4: =SUM(C4:I4) | K4: 207 | L4: =IF(K4=0,0,J4/K4) | M4: =IF(K4=0,"—",REPT("▓",MIN(20,INT(J4/K4*20)))&REPT("░",MAX(0,20-MIN(20,INT(J4/K4*20))))) | N4: =IF(J4=0,"⬜",IF(J4/K4<0.8,"🟢",IF(J4/K4<=1,"🟡","🔴")))
B5: 🛒 Alimentation | C5: 0 | D5: 0 | E5: 0 | F5: 0 | G5: 0 | H5: 0 | I5: 0 | J5: =SUM(C5:I5) | K5: 104 | L5: =IF(K5=0,0,J5/K5) | M5: =IF(K5=0,"—",REPT("▓",MIN(20,INT(J5/K5*20)))&REPT("░",MAX(0,20-MIN(20,INT(J5/K5*20))))) | N5: =IF(J5=0,"⬜",IF(J5/K5<0.8,"🟢",IF(J5/K5<=1,"🟡","🔴")))
B6: 🚗 Transport | C6: 0 | D6: 0 | E6: 0 | F6: 0 | G6: 0 | H6: 0 | I6: 0 | J6: =SUM(C6:I6) | K6: 46 | L6: =IF(K6=0,0,J6/K6) | M6: =IF(K6=0,"—",REPT("▓",MIN(20,INT(J6/K6*20)))&REPT("░",MAX(0,20-MIN(20,INT(J6/K6*20))))) | N6: =IF(J6=0,"⬜",IF(J6/K6<0.8,"🟢",IF(J6/K6<=1,"🟡","🔴")))
B7: 💊 Santé | C7: 0 | D7: 0 | E7: 0 | F7: 0 | G7: 0 | H7: 0 | I7: 0 | J7: =SUM(C7:I7) | K7: 23 | L7: =IF(K7=0,0,J7/K7) | M7: =IF(K7=0,"—",REPT("▓",MIN(20,INT(J7/K7*20)))&REPT("░",MAX(0,20-MIN(20,INT(J7/K7*20))))) | N7: =IF(J7=0,"⬜",IF(J7/K7<0.8,"🟢",IF(J7/K7<=1,"🟡","🔴")))
B8: 🎮 Loisirs | C8: 0 | D8: 0 | E8: 0 | F8: 0 | G8: 0 | H8: 0 | I8: 0 | J8: =SUM(C8:I8) | K8: 35 | L8: =IF(K8=0,0,J8/K8) | M8: =IF(K8=0,"—",REPT("▓",MIN(20,INT(J8/K8*20)))&REPT("░",MAX(0,20-MIN(20,INT(J8/K8*20))))) | N8: =IF(J8=0,"⬜",IF(J8/K8<0.8,"🟢",IF(J8/K8<=1,"🟡","🔴")))
